2025-05-29 23:51:31,679 INFO    MainThread:1352753 [wandb_setup.py:_flush():70] Current SDK version is 0.19.11
2025-05-29 23:51:31,679 INFO    MainThread:1352753 [wandb_setup.py:_flush():70] Configure stats pid to 1352753
2025-05-29 23:51:31,679 INFO    MainThread:1352753 [wandb_setup.py:_flush():70] Loading settings from /root/.config/wandb/settings
2025-05-29 23:51:31,679 INFO    MainThread:1352753 [wandb_setup.py:_flush():70] Loading settings from /home/sunxiaofeng/nanoGPT/wandb/settings
2025-05-29 23:51:31,679 INFO    MainThread:1352753 [wandb_setup.py:_flush():70] Loading settings from environment variables
2025-05-29 23:51:31,679 INFO    MainThread:1352753 [wandb_init.py:setup_run_log_directory():724] Logging user logs to /home/sunxiaofeng/nanoGPT/wandb/run-20250529_235131-afhy5l94/logs/debug.log
2025-05-29 23:51:31,679 INFO    MainThread:1352753 [wandb_init.py:setup_run_log_directory():725] Logging internal logs to /home/sunxiaofeng/nanoGPT/wandb/run-20250529_235131-afhy5l94/logs/debug-internal.log
2025-05-29 23:51:31,679 INFO    MainThread:1352753 [wandb_init.py:init():852] calling init triggers
2025-05-29 23:51:31,679 INFO    MainThread:1352753 [wandb_init.py:init():857] wandb.init called with sweep_config: {}
config: {'out_dir': 'out', 'eval_interval': 1000, 'log_interval': 10, 'eval_iters': 200, 'eval_only': False, 'always_save_checkpoint': True, 'init_from': 'scratch', 'wandb_log': True, 'wandb_project': 'owt', 'wandb_run_name': 'gpt2-124M', 'dataset': 'openwebtext', 'gradient_accumulation_steps': 40, 'batch_size': 12, 'block_size': 1024, 'n_layer': 12, 'n_head': 12, 'n_embd': 768, 'dropout': 0.0, 'bias': False, 'learning_rate': 0.0006, 'max_iters': 600000, 'weight_decay': 0.1, 'beta1': 0.9, 'beta2': 0.95, 'grad_clip': 1.0, 'decay_lr': True, 'warmup_iters': 2000, 'lr_decay_iters': 600000, 'min_lr': 6e-05, 'backend': 'hccl', 'device': 'npu', 'dtype': 'bfloat16', 'compile': False, '_wandb': {}}
2025-05-29 23:51:31,680 INFO    MainThread:1352753 [wandb_init.py:init():893] starting backend
2025-05-29 23:51:31,680 INFO    MainThread:1352753 [wandb_init.py:init():897] sending inform_init request
2025-05-29 23:51:31,685 INFO    MainThread:1352753 [backend.py:_multiprocessing_setup():101] multiprocessing start_methods=fork,spawn,forkserver, using: spawn
2025-05-29 23:51:31,685 INFO    MainThread:1352753 [wandb_init.py:init():907] backend started and connected
2025-05-29 23:51:31,687 INFO    MainThread:1352753 [wandb_init.py:init():1005] updated telemetry
2025-05-29 23:51:31,694 INFO    MainThread:1352753 [wandb_init.py:init():1029] communicating run to backend with 90.0 second timeout
2025-05-29 23:51:33,852 INFO    MainThread:1352753 [wandb_init.py:init():1104] starting run threads in backend
2025-05-29 23:51:34,147 INFO    MainThread:1352753 [wandb_run.py:_console_start():2573] atexit reg
2025-05-29 23:51:34,148 INFO    MainThread:1352753 [wandb_run.py:_redirect():2421] redirect: wrap_raw
2025-05-29 23:51:34,148 INFO    MainThread:1352753 [wandb_run.py:_redirect():2490] Wrapping output streams.
2025-05-29 23:51:34,148 INFO    MainThread:1352753 [wandb_run.py:_redirect():2513] Redirects installed.
2025-05-29 23:51:34,150 INFO    MainThread:1352753 [wandb_init.py:init():1150] run started, returning control to user process
2025-05-30 17:13:22,629 INFO    MsgRouterThr:1352753 [mailbox.py:close():129] [no run ID] Closing mailbox, abandoning 1 handles.
2025-05-30 17:14:09,629 ERROR   MainThread:1352753 [redirect.py:_on_write():664] [no run ID] error in stderr callback
Traceback (most recent call last):
  File "/root/anaconda3/envs/gpt2/lib/python3.10/multiprocessing/managers.py", line 810, in _callmethod
    conn = self._tls.connection
AttributeError: 'ForkAwareLocal' object has no attribute 'connection'

During handling of the above exception, another exception occurred:

Traceback (most recent call last):
  File "/root/anaconda3/envs/gpt2/lib/python3.10/multiprocessing/util.py", line 300, in _run_finalizers
    finalizer()
  File "/root/anaconda3/envs/gpt2/lib/python3.10/multiprocessing/util.py", line 224, in __call__
    res = self._callback(*self._args, **self._kwargs)
  File "/usr/local/Ascend/ascend-toolkit/latest/python/site-packages/tbe/common/repository_manager/route.py", line 54, in wrapper
    return func(cls, *args, **kwargs)
  File "/usr/local/Ascend/ascend-toolkit/latest/python/site-packages/tbe/common/repository_manager/route.py", line 208, in finalize
    cls.cann_kb_mgr.finalize()
  File "/usr/local/Ascend/ascend-toolkit/latest/python/site-packages/tbe/common/repository_manager/cann_kb_manager/knowledge_bank_manager.py", line 42, in finalize
    self.__static_mgr.close()
  File "/usr/local/Ascend/ascend-toolkit/latest/python/site-packages/tbe/common/repository_manager/cann_kb_manager/base_manager.py", line 339, in close
    for name in copy.deepcopy(self.write_kb.keys()):
  File "<string>", line 2, in keys
  File "/root/anaconda3/envs/gpt2/lib/python3.10/multiprocessing/managers.py", line 814, in _callmethod
    self._connect()
  File "/root/anaconda3/envs/gpt2/lib/python3.10/multiprocessing/managers.py", line 801, in _connect
    conn = self._Client(self._token.address, authkey=self._authkey)
  File "/root/anaconda3/envs/gpt2/lib/python3.10/multiprocessing/connection.py", line 502, in Client
    c = SocketClient(address)
  File "/root/anaconda3/envs/gpt2/lib/python3.10/multiprocessing/connection.py", line 630, in SocketClient
    s.connect(address)
ConnectionRefusedError: [Errno 111] Connection refused

During handling of the above exception, another exception occurred:

Traceback (most recent call last):
  File "/root/anaconda3/envs/gpt2/lib/python3.10/site-packages/wandb/sdk/lib/redirect.py", line 662, in _on_write
    cb(written_data)
  File "/root/anaconda3/envs/gpt2/lib/python3.10/site-packages/wandb/sdk/wandb_run.py", line 2500, in <lambda>
    lambda data: self._console_raw_callback("stderr", data),
  File "/root/anaconda3/envs/gpt2/lib/python3.10/site-packages/wandb/sdk/wandb_run.py", line 406, in wrapper
    return func(self, *args, **kwargs)
  File "/root/anaconda3/envs/gpt2/lib/python3.10/site-packages/wandb/sdk/wandb_run.py", line 464, in wrapper_fn
    return func(self, *args, **kwargs)
  File "/root/anaconda3/envs/gpt2/lib/python3.10/site-packages/wandb/sdk/wandb_run.py", line 1639, in _console_raw_callback
    self._backend.interface.publish_output_raw(name, data)
  File "/root/anaconda3/envs/gpt2/lib/python3.10/site-packages/wandb/sdk/interface/interface.py", line 762, in publish_output_raw
    self._publish_output_raw(o)
  File "/root/anaconda3/envs/gpt2/lib/python3.10/site-packages/wandb/sdk/interface/interface_shared.py", line 38, in _publish_output_raw
    self._publish(rec)
  File "/root/anaconda3/envs/gpt2/lib/python3.10/site-packages/wandb/sdk/interface/interface_sock.py", line 39, in _publish
    self._sock_client.send_record_publish(record)
  File "/root/anaconda3/envs/gpt2/lib/python3.10/site-packages/wandb/sdk/lib/sock_client.py", line 174, in send_record_publish
    self.send_server_request(server_req)
  File "/root/anaconda3/envs/gpt2/lib/python3.10/site-packages/wandb/sdk/lib/sock_client.py", line 154, in send_server_request
    self._send_message(msg)
  File "/root/anaconda3/envs/gpt2/lib/python3.10/site-packages/wandb/sdk/lib/sock_client.py", line 151, in _send_message
    self._sendall_with_error_handle(header + data)
  File "/root/anaconda3/envs/gpt2/lib/python3.10/site-packages/wandb/sdk/lib/sock_client.py", line 130, in _sendall_with_error_handle
    sent = self._sock.send(data)
BrokenPipeError: [Errno 32] Broken pipe
2025-05-30 17:14:09,631 ERROR   MainThread:1352753 [redirect.py:_on_write():664] [no run ID] error in stderr callback
Traceback (most recent call last):
  File "/root/anaconda3/envs/gpt2/lib/python3.10/multiprocessing/managers.py", line 810, in _callmethod
    conn = self._tls.connection
AttributeError: 'ForkAwareLocal' object has no attribute 'connection'

During handling of the above exception, another exception occurred:

Traceback (most recent call last):
  File "/root/anaconda3/envs/gpt2/lib/python3.10/multiprocessing/util.py", line 300, in _run_finalizers
    finalizer()
  File "/root/anaconda3/envs/gpt2/lib/python3.10/multiprocessing/util.py", line 224, in __call__
    res = self._callback(*self._args, **self._kwargs)
  File "/usr/local/Ascend/ascend-toolkit/latest/python/site-packages/tbe/common/repository_manager/route.py", line 54, in wrapper
    return func(cls, *args, **kwargs)
  File "/usr/local/Ascend/ascend-toolkit/latest/python/site-packages/tbe/common/repository_manager/route.py", line 208, in finalize
    cls.cann_kb_mgr.finalize()
  File "/usr/local/Ascend/ascend-toolkit/latest/python/site-packages/tbe/common/repository_manager/cann_kb_manager/knowledge_bank_manager.py", line 42, in finalize
    self.__static_mgr.close()
  File "/usr/local/Ascend/ascend-toolkit/latest/python/site-packages/tbe/common/repository_manager/cann_kb_manager/base_manager.py", line 339, in close
    for name in copy.deepcopy(self.write_kb.keys()):
  File "<string>", line 2, in keys
  File "/root/anaconda3/envs/gpt2/lib/python3.10/multiprocessing/managers.py", line 814, in _callmethod
    self._connect()
  File "/root/anaconda3/envs/gpt2/lib/python3.10/multiprocessing/managers.py", line 801, in _connect
    conn = self._Client(self._token.address, authkey=self._authkey)
  File "/root/anaconda3/envs/gpt2/lib/python3.10/multiprocessing/connection.py", line 502, in Client
    c = SocketClient(address)
  File "/root/anaconda3/envs/gpt2/lib/python3.10/multiprocessing/connection.py", line 630, in SocketClient
    s.connect(address)
ConnectionRefusedError: [Errno 111] Connection refused

During handling of the above exception, another exception occurred:

Traceback (most recent call last):
  File "/root/anaconda3/envs/gpt2/lib/python3.10/site-packages/wandb/sdk/lib/redirect.py", line 662, in _on_write
    cb(written_data)
  File "/root/anaconda3/envs/gpt2/lib/python3.10/site-packages/wandb/sdk/wandb_run.py", line 2500, in <lambda>
    lambda data: self._console_raw_callback("stderr", data),
  File "/root/anaconda3/envs/gpt2/lib/python3.10/site-packages/wandb/sdk/wandb_run.py", line 406, in wrapper
    return func(self, *args, **kwargs)
  File "/root/anaconda3/envs/gpt2/lib/python3.10/site-packages/wandb/sdk/wandb_run.py", line 464, in wrapper_fn
    return func(self, *args, **kwargs)
  File "/root/anaconda3/envs/gpt2/lib/python3.10/site-packages/wandb/sdk/wandb_run.py", line 1639, in _console_raw_callback
    self._backend.interface.publish_output_raw(name, data)
  File "/root/anaconda3/envs/gpt2/lib/python3.10/site-packages/wandb/sdk/interface/interface.py", line 762, in publish_output_raw
    self._publish_output_raw(o)
  File "/root/anaconda3/envs/gpt2/lib/python3.10/site-packages/wandb/sdk/interface/interface_shared.py", line 38, in _publish_output_raw
    self._publish(rec)
  File "/root/anaconda3/envs/gpt2/lib/python3.10/site-packages/wandb/sdk/interface/interface_sock.py", line 39, in _publish
    self._sock_client.send_record_publish(record)
  File "/root/anaconda3/envs/gpt2/lib/python3.10/site-packages/wandb/sdk/lib/sock_client.py", line 174, in send_record_publish
    self.send_server_request(server_req)
  File "/root/anaconda3/envs/gpt2/lib/python3.10/site-packages/wandb/sdk/lib/sock_client.py", line 154, in send_server_request
    self._send_message(msg)
  File "/root/anaconda3/envs/gpt2/lib/python3.10/site-packages/wandb/sdk/lib/sock_client.py", line 151, in _send_message
    self._sendall_with_error_handle(header + data)
  File "/root/anaconda3/envs/gpt2/lib/python3.10/site-packages/wandb/sdk/lib/sock_client.py", line 130, in _sendall_with_error_handle
    sent = self._sock.send(data)
BrokenPipeError: [Errno 32] Broken pipe
2025-05-30 17:14:09,632 ERROR   MainThread:1352753 [redirect.py:_on_write():664] [no run ID] error in stderr callback
Traceback (most recent call last):
  File "/root/anaconda3/envs/gpt2/lib/python3.10/multiprocessing/managers.py", line 810, in _callmethod
    conn = self._tls.connection
AttributeError: 'ForkAwareLocal' object has no attribute 'connection'

During handling of the above exception, another exception occurred:

Traceback (most recent call last):
  File "/root/anaconda3/envs/gpt2/lib/python3.10/multiprocessing/util.py", line 300, in _run_finalizers
    finalizer()
  File "/root/anaconda3/envs/gpt2/lib/python3.10/multiprocessing/util.py", line 224, in __call__
    res = self._callback(*self._args, **self._kwargs)
  File "/usr/local/Ascend/ascend-toolkit/latest/python/site-packages/tbe/common/repository_manager/route.py", line 54, in wrapper
    return func(cls, *args, **kwargs)
  File "/usr/local/Ascend/ascend-toolkit/latest/python/site-packages/tbe/common/repository_manager/route.py", line 208, in finalize
    cls.cann_kb_mgr.finalize()
  File "/usr/local/Ascend/ascend-toolkit/latest/python/site-packages/tbe/common/repository_manager/cann_kb_manager/knowledge_bank_manager.py", line 42, in finalize
    self.__static_mgr.close()
  File "/usr/local/Ascend/ascend-toolkit/latest/python/site-packages/tbe/common/repository_manager/cann_kb_manager/base_manager.py", line 339, in close
    for name in copy.deepcopy(self.write_kb.keys()):
  File "<string>", line 2, in keys
  File "/root/anaconda3/envs/gpt2/lib/python3.10/multiprocessing/managers.py", line 814, in _callmethod
    self._connect()
  File "/root/anaconda3/envs/gpt2/lib/python3.10/multiprocessing/managers.py", line 801, in _connect
    conn = self._Client(self._token.address, authkey=self._authkey)
  File "/root/anaconda3/envs/gpt2/lib/python3.10/multiprocessing/connection.py", line 502, in Client
    c = SocketClient(address)
  File "/root/anaconda3/envs/gpt2/lib/python3.10/multiprocessing/connection.py", line 630, in SocketClient
    s.connect(address)
ConnectionRefusedError: [Errno 111] Connection refused

During handling of the above exception, another exception occurred:

Traceback (most recent call last):
  File "/root/anaconda3/envs/gpt2/lib/python3.10/site-packages/wandb/sdk/lib/redirect.py", line 662, in _on_write
    cb(written_data)
  File "/root/anaconda3/envs/gpt2/lib/python3.10/site-packages/wandb/sdk/wandb_run.py", line 2500, in <lambda>
    lambda data: self._console_raw_callback("stderr", data),
  File "/root/anaconda3/envs/gpt2/lib/python3.10/site-packages/wandb/sdk/wandb_run.py", line 406, in wrapper
    return func(self, *args, **kwargs)
  File "/root/anaconda3/envs/gpt2/lib/python3.10/site-packages/wandb/sdk/wandb_run.py", line 464, in wrapper_fn
    return func(self, *args, **kwargs)
  File "/root/anaconda3/envs/gpt2/lib/python3.10/site-packages/wandb/sdk/wandb_run.py", line 1639, in _console_raw_callback
    self._backend.interface.publish_output_raw(name, data)
  File "/root/anaconda3/envs/gpt2/lib/python3.10/site-packages/wandb/sdk/interface/interface.py", line 762, in publish_output_raw
    self._publish_output_raw(o)
  File "/root/anaconda3/envs/gpt2/lib/python3.10/site-packages/wandb/sdk/interface/interface_shared.py", line 38, in _publish_output_raw
    self._publish(rec)
  File "/root/anaconda3/envs/gpt2/lib/python3.10/site-packages/wandb/sdk/interface/interface_sock.py", line 39, in _publish
    self._sock_client.send_record_publish(record)
  File "/root/anaconda3/envs/gpt2/lib/python3.10/site-packages/wandb/sdk/lib/sock_client.py", line 174, in send_record_publish
    self.send_server_request(server_req)
  File "/root/anaconda3/envs/gpt2/lib/python3.10/site-packages/wandb/sdk/lib/sock_client.py", line 154, in send_server_request
    self._send_message(msg)
  File "/root/anaconda3/envs/gpt2/lib/python3.10/site-packages/wandb/sdk/lib/sock_client.py", line 151, in _send_message
    self._sendall_with_error_handle(header + data)
  File "/root/anaconda3/envs/gpt2/lib/python3.10/site-packages/wandb/sdk/lib/sock_client.py", line 130, in _sendall_with_error_handle
    sent = self._sock.send(data)
BrokenPipeError: [Errno 32] Broken pipe
2025-05-30 17:14:09,633 ERROR   MainThread:1352753 [redirect.py:_on_write():664] [no run ID] error in stderr callback
Traceback (most recent call last):
  File "/root/anaconda3/envs/gpt2/lib/python3.10/multiprocessing/managers.py", line 810, in _callmethod
    conn = self._tls.connection
AttributeError: 'ForkAwareLocal' object has no attribute 'connection'

During handling of the above exception, another exception occurred:

Traceback (most recent call last):
  File "/root/anaconda3/envs/gpt2/lib/python3.10/multiprocessing/util.py", line 300, in _run_finalizers
    finalizer()
  File "/root/anaconda3/envs/gpt2/lib/python3.10/multiprocessing/util.py", line 224, in __call__
    res = self._callback(*self._args, **self._kwargs)
  File "/usr/local/Ascend/ascend-toolkit/latest/python/site-packages/tbe/common/repository_manager/route.py", line 54, in wrapper
    return func(cls, *args, **kwargs)
  File "/usr/local/Ascend/ascend-toolkit/latest/python/site-packages/tbe/common/repository_manager/route.py", line 208, in finalize
    cls.cann_kb_mgr.finalize()
  File "/usr/local/Ascend/ascend-toolkit/latest/python/site-packages/tbe/common/repository_manager/cann_kb_manager/knowledge_bank_manager.py", line 42, in finalize
    self.__static_mgr.close()
  File "/usr/local/Ascend/ascend-toolkit/latest/python/site-packages/tbe/common/repository_manager/cann_kb_manager/base_manager.py", line 339, in close
    for name in copy.deepcopy(self.write_kb.keys()):
  File "<string>", line 2, in keys
  File "/root/anaconda3/envs/gpt2/lib/python3.10/multiprocessing/managers.py", line 814, in _callmethod
    self._connect()
  File "/root/anaconda3/envs/gpt2/lib/python3.10/multiprocessing/managers.py", line 801, in _connect
    conn = self._Client(self._token.address, authkey=self._authkey)
  File "/root/anaconda3/envs/gpt2/lib/python3.10/multiprocessing/connection.py", line 502, in Client
    c = SocketClient(address)
  File "/root/anaconda3/envs/gpt2/lib/python3.10/multiprocessing/connection.py", line 630, in SocketClient
    s.connect(address)
ConnectionRefusedError: [Errno 111] Connection refused

During handling of the above exception, another exception occurred:

Traceback (most recent call last):
  File "/root/anaconda3/envs/gpt2/lib/python3.10/site-packages/wandb/sdk/lib/redirect.py", line 662, in _on_write
    cb(written_data)
  File "/root/anaconda3/envs/gpt2/lib/python3.10/site-packages/wandb/sdk/wandb_run.py", line 2500, in <lambda>
    lambda data: self._console_raw_callback("stderr", data),
  File "/root/anaconda3/envs/gpt2/lib/python3.10/site-packages/wandb/sdk/wandb_run.py", line 406, in wrapper
    return func(self, *args, **kwargs)
  File "/root/anaconda3/envs/gpt2/lib/python3.10/site-packages/wandb/sdk/wandb_run.py", line 464, in wrapper_fn
    return func(self, *args, **kwargs)
  File "/root/anaconda3/envs/gpt2/lib/python3.10/site-packages/wandb/sdk/wandb_run.py", line 1639, in _console_raw_callback
    self._backend.interface.publish_output_raw(name, data)
  File "/root/anaconda3/envs/gpt2/lib/python3.10/site-packages/wandb/sdk/interface/interface.py", line 762, in publish_output_raw
    self._publish_output_raw(o)
  File "/root/anaconda3/envs/gpt2/lib/python3.10/site-packages/wandb/sdk/interface/interface_shared.py", line 38, in _publish_output_raw
    self._publish(rec)
  File "/root/anaconda3/envs/gpt2/lib/python3.10/site-packages/wandb/sdk/interface/interface_sock.py", line 39, in _publish
    self._sock_client.send_record_publish(record)
  File "/root/anaconda3/envs/gpt2/lib/python3.10/site-packages/wandb/sdk/lib/sock_client.py", line 174, in send_record_publish
    self.send_server_request(server_req)
  File "/root/anaconda3/envs/gpt2/lib/python3.10/site-packages/wandb/sdk/lib/sock_client.py", line 154, in send_server_request
    self._send_message(msg)
  File "/root/anaconda3/envs/gpt2/lib/python3.10/site-packages/wandb/sdk/lib/sock_client.py", line 151, in _send_message
    self._sendall_with_error_handle(header + data)
  File "/root/anaconda3/envs/gpt2/lib/python3.10/site-packages/wandb/sdk/lib/sock_client.py", line 130, in _sendall_with_error_handle
    sent = self._sock.send(data)
BrokenPipeError: [Errno 32] Broken pipe
2025-05-30 17:14:09,633 ERROR   MainThread:1352753 [redirect.py:_on_write():664] [no run ID] error in stderr callback
Traceback (most recent call last):
  File "/root/anaconda3/envs/gpt2/lib/python3.10/multiprocessing/managers.py", line 810, in _callmethod
    conn = self._tls.connection
AttributeError: 'ForkAwareLocal' object has no attribute 'connection'

During handling of the above exception, another exception occurred:

Traceback (most recent call last):
  File "/root/anaconda3/envs/gpt2/lib/python3.10/multiprocessing/util.py", line 300, in _run_finalizers
    finalizer()
  File "/root/anaconda3/envs/gpt2/lib/python3.10/multiprocessing/util.py", line 224, in __call__
    res = self._callback(*self._args, **self._kwargs)
  File "/usr/local/Ascend/ascend-toolkit/latest/python/site-packages/tbe/common/repository_manager/route.py", line 54, in wrapper
    return func(cls, *args, **kwargs)
  File "/usr/local/Ascend/ascend-toolkit/latest/python/site-packages/tbe/common/repository_manager/route.py", line 208, in finalize
    cls.cann_kb_mgr.finalize()
  File "/usr/local/Ascend/ascend-toolkit/latest/python/site-packages/tbe/common/repository_manager/cann_kb_manager/knowledge_bank_manager.py", line 42, in finalize
    self.__static_mgr.close()
  File "/usr/local/Ascend/ascend-toolkit/latest/python/site-packages/tbe/common/repository_manager/cann_kb_manager/base_manager.py", line 339, in close
    for name in copy.deepcopy(self.write_kb.keys()):
  File "<string>", line 2, in keys
  File "/root/anaconda3/envs/gpt2/lib/python3.10/multiprocessing/managers.py", line 814, in _callmethod
    self._connect()
  File "/root/anaconda3/envs/gpt2/lib/python3.10/multiprocessing/managers.py", line 801, in _connect
    conn = self._Client(self._token.address, authkey=self._authkey)
  File "/root/anaconda3/envs/gpt2/lib/python3.10/multiprocessing/connection.py", line 502, in Client
    c = SocketClient(address)
  File "/root/anaconda3/envs/gpt2/lib/python3.10/multiprocessing/connection.py", line 630, in SocketClient
    s.connect(address)
ConnectionRefusedError: [Errno 111] Connection refused

During handling of the above exception, another exception occurred:

Traceback (most recent call last):
  File "/root/anaconda3/envs/gpt2/lib/python3.10/site-packages/wandb/sdk/lib/redirect.py", line 662, in _on_write
    cb(written_data)
  File "/root/anaconda3/envs/gpt2/lib/python3.10/site-packages/wandb/sdk/wandb_run.py", line 2500, in <lambda>
    lambda data: self._console_raw_callback("stderr", data),
  File "/root/anaconda3/envs/gpt2/lib/python3.10/site-packages/wandb/sdk/wandb_run.py", line 406, in wrapper
    return func(self, *args, **kwargs)
  File "/root/anaconda3/envs/gpt2/lib/python3.10/site-packages/wandb/sdk/wandb_run.py", line 464, in wrapper_fn
    return func(self, *args, **kwargs)
  File "/root/anaconda3/envs/gpt2/lib/python3.10/site-packages/wandb/sdk/wandb_run.py", line 1639, in _console_raw_callback
    self._backend.interface.publish_output_raw(name, data)
  File "/root/anaconda3/envs/gpt2/lib/python3.10/site-packages/wandb/sdk/interface/interface.py", line 762, in publish_output_raw
    self._publish_output_raw(o)
  File "/root/anaconda3/envs/gpt2/lib/python3.10/site-packages/wandb/sdk/interface/interface_shared.py", line 38, in _publish_output_raw
    self._publish(rec)
  File "/root/anaconda3/envs/gpt2/lib/python3.10/site-packages/wandb/sdk/interface/interface_sock.py", line 39, in _publish
    self._sock_client.send_record_publish(record)
  File "/root/anaconda3/envs/gpt2/lib/python3.10/site-packages/wandb/sdk/lib/sock_client.py", line 174, in send_record_publish
    self.send_server_request(server_req)
  File "/root/anaconda3/envs/gpt2/lib/python3.10/site-packages/wandb/sdk/lib/sock_client.py", line 154, in send_server_request
    self._send_message(msg)
  File "/root/anaconda3/envs/gpt2/lib/python3.10/site-packages/wandb/sdk/lib/sock_client.py", line 151, in _send_message
    self._sendall_with_error_handle(header + data)
  File "/root/anaconda3/envs/gpt2/lib/python3.10/site-packages/wandb/sdk/lib/sock_client.py", line 130, in _sendall_with_error_handle
    sent = self._sock.send(data)
BrokenPipeError: [Errno 32] Broken pipe
2025-05-30 17:14:09,634 ERROR   MainThread:1352753 [redirect.py:_on_write():664] [no run ID] error in stderr callback
Traceback (most recent call last):
  File "/root/anaconda3/envs/gpt2/lib/python3.10/multiprocessing/managers.py", line 810, in _callmethod
    conn = self._tls.connection
AttributeError: 'ForkAwareLocal' object has no attribute 'connection'

During handling of the above exception, another exception occurred:

Traceback (most recent call last):
  File "/root/anaconda3/envs/gpt2/lib/python3.10/multiprocessing/util.py", line 300, in _run_finalizers
    finalizer()
  File "/root/anaconda3/envs/gpt2/lib/python3.10/multiprocessing/util.py", line 224, in __call__
    res = self._callback(*self._args, **self._kwargs)
  File "/usr/local/Ascend/ascend-toolkit/latest/python/site-packages/tbe/common/repository_manager/route.py", line 54, in wrapper
    return func(cls, *args, **kwargs)
  File "/usr/local/Ascend/ascend-toolkit/latest/python/site-packages/tbe/common/repository_manager/route.py", line 208, in finalize
    cls.cann_kb_mgr.finalize()
  File "/usr/local/Ascend/ascend-toolkit/latest/python/site-packages/tbe/common/repository_manager/cann_kb_manager/knowledge_bank_manager.py", line 42, in finalize
    self.__static_mgr.close()
  File "/usr/local/Ascend/ascend-toolkit/latest/python/site-packages/tbe/common/repository_manager/cann_kb_manager/base_manager.py", line 339, in close
    for name in copy.deepcopy(self.write_kb.keys()):
  File "<string>", line 2, in keys
  File "/root/anaconda3/envs/gpt2/lib/python3.10/multiprocessing/managers.py", line 814, in _callmethod
    self._connect()
  File "/root/anaconda3/envs/gpt2/lib/python3.10/multiprocessing/managers.py", line 801, in _connect
    conn = self._Client(self._token.address, authkey=self._authkey)
  File "/root/anaconda3/envs/gpt2/lib/python3.10/multiprocessing/connection.py", line 502, in Client
    c = SocketClient(address)
  File "/root/anaconda3/envs/gpt2/lib/python3.10/multiprocessing/connection.py", line 630, in SocketClient
    s.connect(address)
ConnectionRefusedError: [Errno 111] Connection refused

During handling of the above exception, another exception occurred:

Traceback (most recent call last):
  File "/root/anaconda3/envs/gpt2/lib/python3.10/site-packages/wandb/sdk/lib/redirect.py", line 662, in _on_write
    cb(written_data)
  File "/root/anaconda3/envs/gpt2/lib/python3.10/site-packages/wandb/sdk/wandb_run.py", line 2500, in <lambda>
    lambda data: self._console_raw_callback("stderr", data),
  File "/root/anaconda3/envs/gpt2/lib/python3.10/site-packages/wandb/sdk/wandb_run.py", line 406, in wrapper
    return func(self, *args, **kwargs)
  File "/root/anaconda3/envs/gpt2/lib/python3.10/site-packages/wandb/sdk/wandb_run.py", line 464, in wrapper_fn
    return func(self, *args, **kwargs)
  File "/root/anaconda3/envs/gpt2/lib/python3.10/site-packages/wandb/sdk/wandb_run.py", line 1639, in _console_raw_callback
    self._backend.interface.publish_output_raw(name, data)
  File "/root/anaconda3/envs/gpt2/lib/python3.10/site-packages/wandb/sdk/interface/interface.py", line 762, in publish_output_raw
    self._publish_output_raw(o)
  File "/root/anaconda3/envs/gpt2/lib/python3.10/site-packages/wandb/sdk/interface/interface_shared.py", line 38, in _publish_output_raw
    self._publish(rec)
  File "/root/anaconda3/envs/gpt2/lib/python3.10/site-packages/wandb/sdk/interface/interface_sock.py", line 39, in _publish
    self._sock_client.send_record_publish(record)
  File "/root/anaconda3/envs/gpt2/lib/python3.10/site-packages/wandb/sdk/lib/sock_client.py", line 174, in send_record_publish
    self.send_server_request(server_req)
  File "/root/anaconda3/envs/gpt2/lib/python3.10/site-packages/wandb/sdk/lib/sock_client.py", line 154, in send_server_request
    self._send_message(msg)
  File "/root/anaconda3/envs/gpt2/lib/python3.10/site-packages/wandb/sdk/lib/sock_client.py", line 151, in _send_message
    self._sendall_with_error_handle(header + data)
  File "/root/anaconda3/envs/gpt2/lib/python3.10/site-packages/wandb/sdk/lib/sock_client.py", line 130, in _sendall_with_error_handle
    sent = self._sock.send(data)
BrokenPipeError: [Errno 32] Broken pipe
2025-05-30 17:14:09,635 ERROR   MainThread:1352753 [redirect.py:_on_write():664] [no run ID] error in stderr callback
Traceback (most recent call last):
  File "/root/anaconda3/envs/gpt2/lib/python3.10/multiprocessing/managers.py", line 810, in _callmethod
    conn = self._tls.connection
AttributeError: 'ForkAwareLocal' object has no attribute 'connection'

During handling of the above exception, another exception occurred:

Traceback (most recent call last):
  File "/root/anaconda3/envs/gpt2/lib/python3.10/multiprocessing/util.py", line 300, in _run_finalizers
    finalizer()
  File "/root/anaconda3/envs/gpt2/lib/python3.10/multiprocessing/util.py", line 224, in __call__
    res = self._callback(*self._args, **self._kwargs)
  File "/usr/local/Ascend/ascend-toolkit/latest/python/site-packages/tbe/common/repository_manager/route.py", line 54, in wrapper
    return func(cls, *args, **kwargs)
  File "/usr/local/Ascend/ascend-toolkit/latest/python/site-packages/tbe/common/repository_manager/route.py", line 208, in finalize
    cls.cann_kb_mgr.finalize()
  File "/usr/local/Ascend/ascend-toolkit/latest/python/site-packages/tbe/common/repository_manager/cann_kb_manager/knowledge_bank_manager.py", line 42, in finalize
    self.__static_mgr.close()
  File "/usr/local/Ascend/ascend-toolkit/latest/python/site-packages/tbe/common/repository_manager/cann_kb_manager/base_manager.py", line 339, in close
    for name in copy.deepcopy(self.write_kb.keys()):
  File "<string>", line 2, in keys
  File "/root/anaconda3/envs/gpt2/lib/python3.10/multiprocessing/managers.py", line 814, in _callmethod
    self._connect()
  File "/root/anaconda3/envs/gpt2/lib/python3.10/multiprocessing/managers.py", line 801, in _connect
    conn = self._Client(self._token.address, authkey=self._authkey)
  File "/root/anaconda3/envs/gpt2/lib/python3.10/multiprocessing/connection.py", line 502, in Client
    c = SocketClient(address)
  File "/root/anaconda3/envs/gpt2/lib/python3.10/multiprocessing/connection.py", line 630, in SocketClient
    s.connect(address)
ConnectionRefusedError: [Errno 111] Connection refused

During handling of the above exception, another exception occurred:

Traceback (most recent call last):
  File "/root/anaconda3/envs/gpt2/lib/python3.10/site-packages/wandb/sdk/lib/redirect.py", line 662, in _on_write
    cb(written_data)
  File "/root/anaconda3/envs/gpt2/lib/python3.10/site-packages/wandb/sdk/wandb_run.py", line 2500, in <lambda>
    lambda data: self._console_raw_callback("stderr", data),
  File "/root/anaconda3/envs/gpt2/lib/python3.10/site-packages/wandb/sdk/wandb_run.py", line 406, in wrapper
    return func(self, *args, **kwargs)
  File "/root/anaconda3/envs/gpt2/lib/python3.10/site-packages/wandb/sdk/wandb_run.py", line 464, in wrapper_fn
    return func(self, *args, **kwargs)
  File "/root/anaconda3/envs/gpt2/lib/python3.10/site-packages/wandb/sdk/wandb_run.py", line 1639, in _console_raw_callback
    self._backend.interface.publish_output_raw(name, data)
  File "/root/anaconda3/envs/gpt2/lib/python3.10/site-packages/wandb/sdk/interface/interface.py", line 762, in publish_output_raw
    self._publish_output_raw(o)
  File "/root/anaconda3/envs/gpt2/lib/python3.10/site-packages/wandb/sdk/interface/interface_shared.py", line 38, in _publish_output_raw
    self._publish(rec)
  File "/root/anaconda3/envs/gpt2/lib/python3.10/site-packages/wandb/sdk/interface/interface_sock.py", line 39, in _publish
    self._sock_client.send_record_publish(record)
  File "/root/anaconda3/envs/gpt2/lib/python3.10/site-packages/wandb/sdk/lib/sock_client.py", line 174, in send_record_publish
    self.send_server_request(server_req)
  File "/root/anaconda3/envs/gpt2/lib/python3.10/site-packages/wandb/sdk/lib/sock_client.py", line 154, in send_server_request
    self._send_message(msg)
  File "/root/anaconda3/envs/gpt2/lib/python3.10/site-packages/wandb/sdk/lib/sock_client.py", line 151, in _send_message
    self._sendall_with_error_handle(header + data)
  File "/root/anaconda3/envs/gpt2/lib/python3.10/site-packages/wandb/sdk/lib/sock_client.py", line 130, in _sendall_with_error_handle
    sent = self._sock.send(data)
BrokenPipeError: [Errno 32] Broken pipe
2025-05-30 17:14:09,635 ERROR   MainThread:1352753 [redirect.py:_on_write():664] [no run ID] error in stderr callback
Traceback (most recent call last):
  File "/root/anaconda3/envs/gpt2/lib/python3.10/multiprocessing/managers.py", line 810, in _callmethod
    conn = self._tls.connection
AttributeError: 'ForkAwareLocal' object has no attribute 'connection'

During handling of the above exception, another exception occurred:

Traceback (most recent call last):
  File "/root/anaconda3/envs/gpt2/lib/python3.10/multiprocessing/util.py", line 300, in _run_finalizers
    finalizer()
  File "/root/anaconda3/envs/gpt2/lib/python3.10/multiprocessing/util.py", line 224, in __call__
    res = self._callback(*self._args, **self._kwargs)
  File "/usr/local/Ascend/ascend-toolkit/latest/python/site-packages/tbe/common/repository_manager/route.py", line 54, in wrapper
    return func(cls, *args, **kwargs)
  File "/usr/local/Ascend/ascend-toolkit/latest/python/site-packages/tbe/common/repository_manager/route.py", line 208, in finalize
    cls.cann_kb_mgr.finalize()
  File "/usr/local/Ascend/ascend-toolkit/latest/python/site-packages/tbe/common/repository_manager/cann_kb_manager/knowledge_bank_manager.py", line 42, in finalize
    self.__static_mgr.close()
  File "/usr/local/Ascend/ascend-toolkit/latest/python/site-packages/tbe/common/repository_manager/cann_kb_manager/base_manager.py", line 339, in close
    for name in copy.deepcopy(self.write_kb.keys()):
  File "<string>", line 2, in keys
  File "/root/anaconda3/envs/gpt2/lib/python3.10/multiprocessing/managers.py", line 814, in _callmethod
    self._connect()
  File "/root/anaconda3/envs/gpt2/lib/python3.10/multiprocessing/managers.py", line 801, in _connect
    conn = self._Client(self._token.address, authkey=self._authkey)
  File "/root/anaconda3/envs/gpt2/lib/python3.10/multiprocessing/connection.py", line 502, in Client
    c = SocketClient(address)
  File "/root/anaconda3/envs/gpt2/lib/python3.10/multiprocessing/connection.py", line 630, in SocketClient
    s.connect(address)
ConnectionRefusedError: [Errno 111] Connection refused

During handling of the above exception, another exception occurred:

Traceback (most recent call last):
  File "/root/anaconda3/envs/gpt2/lib/python3.10/site-packages/wandb/sdk/lib/redirect.py", line 662, in _on_write
    cb(written_data)
  File "/root/anaconda3/envs/gpt2/lib/python3.10/site-packages/wandb/sdk/wandb_run.py", line 2500, in <lambda>
    lambda data: self._console_raw_callback("stderr", data),
  File "/root/anaconda3/envs/gpt2/lib/python3.10/site-packages/wandb/sdk/wandb_run.py", line 406, in wrapper
    return func(self, *args, **kwargs)
  File "/root/anaconda3/envs/gpt2/lib/python3.10/site-packages/wandb/sdk/wandb_run.py", line 464, in wrapper_fn
    return func(self, *args, **kwargs)
  File "/root/anaconda3/envs/gpt2/lib/python3.10/site-packages/wandb/sdk/wandb_run.py", line 1639, in _console_raw_callback
    self._backend.interface.publish_output_raw(name, data)
  File "/root/anaconda3/envs/gpt2/lib/python3.10/site-packages/wandb/sdk/interface/interface.py", line 762, in publish_output_raw
    self._publish_output_raw(o)
  File "/root/anaconda3/envs/gpt2/lib/python3.10/site-packages/wandb/sdk/interface/interface_shared.py", line 38, in _publish_output_raw
    self._publish(rec)
  File "/root/anaconda3/envs/gpt2/lib/python3.10/site-packages/wandb/sdk/interface/interface_sock.py", line 39, in _publish
    self._sock_client.send_record_publish(record)
  File "/root/anaconda3/envs/gpt2/lib/python3.10/site-packages/wandb/sdk/lib/sock_client.py", line 174, in send_record_publish
    self.send_server_request(server_req)
  File "/root/anaconda3/envs/gpt2/lib/python3.10/site-packages/wandb/sdk/lib/sock_client.py", line 154, in send_server_request
    self._send_message(msg)
  File "/root/anaconda3/envs/gpt2/lib/python3.10/site-packages/wandb/sdk/lib/sock_client.py", line 151, in _send_message
    self._sendall_with_error_handle(header + data)
  File "/root/anaconda3/envs/gpt2/lib/python3.10/site-packages/wandb/sdk/lib/sock_client.py", line 130, in _sendall_with_error_handle
    sent = self._sock.send(data)
BrokenPipeError: [Errno 32] Broken pipe
2025-05-30 17:14:09,636 ERROR   MainThread:1352753 [redirect.py:_on_write():664] [no run ID] error in stderr callback
Traceback (most recent call last):
  File "/root/anaconda3/envs/gpt2/lib/python3.10/multiprocessing/managers.py", line 810, in _callmethod
    conn = self._tls.connection
AttributeError: 'ForkAwareLocal' object has no attribute 'connection'

During handling of the above exception, another exception occurred:

Traceback (most recent call last):
  File "/root/anaconda3/envs/gpt2/lib/python3.10/multiprocessing/util.py", line 300, in _run_finalizers
    finalizer()
  File "/root/anaconda3/envs/gpt2/lib/python3.10/multiprocessing/util.py", line 224, in __call__
    res = self._callback(*self._args, **self._kwargs)
  File "/usr/local/Ascend/ascend-toolkit/latest/python/site-packages/tbe/common/repository_manager/route.py", line 54, in wrapper
    return func(cls, *args, **kwargs)
  File "/usr/local/Ascend/ascend-toolkit/latest/python/site-packages/tbe/common/repository_manager/route.py", line 208, in finalize
    cls.cann_kb_mgr.finalize()
  File "/usr/local/Ascend/ascend-toolkit/latest/python/site-packages/tbe/common/repository_manager/cann_kb_manager/knowledge_bank_manager.py", line 42, in finalize
    self.__static_mgr.close()
  File "/usr/local/Ascend/ascend-toolkit/latest/python/site-packages/tbe/common/repository_manager/cann_kb_manager/base_manager.py", line 339, in close
    for name in copy.deepcopy(self.write_kb.keys()):
  File "<string>", line 2, in keys
  File "/root/anaconda3/envs/gpt2/lib/python3.10/multiprocessing/managers.py", line 814, in _callmethod
    self._connect()
  File "/root/anaconda3/envs/gpt2/lib/python3.10/multiprocessing/managers.py", line 801, in _connect
    conn = self._Client(self._token.address, authkey=self._authkey)
  File "/root/anaconda3/envs/gpt2/lib/python3.10/multiprocessing/connection.py", line 502, in Client
    c = SocketClient(address)
  File "/root/anaconda3/envs/gpt2/lib/python3.10/multiprocessing/connection.py", line 630, in SocketClient
    s.connect(address)
ConnectionRefusedError: [Errno 111] Connection refused

During handling of the above exception, another exception occurred:

Traceback (most recent call last):
  File "/root/anaconda3/envs/gpt2/lib/python3.10/site-packages/wandb/sdk/lib/redirect.py", line 662, in _on_write
    cb(written_data)
  File "/root/anaconda3/envs/gpt2/lib/python3.10/site-packages/wandb/sdk/wandb_run.py", line 2500, in <lambda>
    lambda data: self._console_raw_callback("stderr", data),
  File "/root/anaconda3/envs/gpt2/lib/python3.10/site-packages/wandb/sdk/wandb_run.py", line 406, in wrapper
    return func(self, *args, **kwargs)
  File "/root/anaconda3/envs/gpt2/lib/python3.10/site-packages/wandb/sdk/wandb_run.py", line 464, in wrapper_fn
    return func(self, *args, **kwargs)
  File "/root/anaconda3/envs/gpt2/lib/python3.10/site-packages/wandb/sdk/wandb_run.py", line 1639, in _console_raw_callback
    self._backend.interface.publish_output_raw(name, data)
  File "/root/anaconda3/envs/gpt2/lib/python3.10/site-packages/wandb/sdk/interface/interface.py", line 762, in publish_output_raw
    self._publish_output_raw(o)
  File "/root/anaconda3/envs/gpt2/lib/python3.10/site-packages/wandb/sdk/interface/interface_shared.py", line 38, in _publish_output_raw
    self._publish(rec)
  File "/root/anaconda3/envs/gpt2/lib/python3.10/site-packages/wandb/sdk/interface/interface_sock.py", line 39, in _publish
    self._sock_client.send_record_publish(record)
  File "/root/anaconda3/envs/gpt2/lib/python3.10/site-packages/wandb/sdk/lib/sock_client.py", line 174, in send_record_publish
    self.send_server_request(server_req)
  File "/root/anaconda3/envs/gpt2/lib/python3.10/site-packages/wandb/sdk/lib/sock_client.py", line 154, in send_server_request
    self._send_message(msg)
  File "/root/anaconda3/envs/gpt2/lib/python3.10/site-packages/wandb/sdk/lib/sock_client.py", line 151, in _send_message
    self._sendall_with_error_handle(header + data)
  File "/root/anaconda3/envs/gpt2/lib/python3.10/site-packages/wandb/sdk/lib/sock_client.py", line 130, in _sendall_with_error_handle
    sent = self._sock.send(data)
BrokenPipeError: [Errno 32] Broken pipe
2025-05-30 17:14:09,637 ERROR   MainThread:1352753 [redirect.py:_on_write():664] [no run ID] error in stderr callback
Traceback (most recent call last):
  File "/root/anaconda3/envs/gpt2/lib/python3.10/multiprocessing/managers.py", line 810, in _callmethod
    conn = self._tls.connection
AttributeError: 'ForkAwareLocal' object has no attribute 'connection'

During handling of the above exception, another exception occurred:

Traceback (most recent call last):
  File "/root/anaconda3/envs/gpt2/lib/python3.10/multiprocessing/util.py", line 300, in _run_finalizers
    finalizer()
  File "/root/anaconda3/envs/gpt2/lib/python3.10/multiprocessing/util.py", line 224, in __call__
    res = self._callback(*self._args, **self._kwargs)
  File "/usr/local/Ascend/ascend-toolkit/latest/python/site-packages/tbe/common/repository_manager/route.py", line 54, in wrapper
    return func(cls, *args, **kwargs)
  File "/usr/local/Ascend/ascend-toolkit/latest/python/site-packages/tbe/common/repository_manager/route.py", line 208, in finalize
    cls.cann_kb_mgr.finalize()
  File "/usr/local/Ascend/ascend-toolkit/latest/python/site-packages/tbe/common/repository_manager/cann_kb_manager/knowledge_bank_manager.py", line 42, in finalize
    self.__static_mgr.close()
  File "/usr/local/Ascend/ascend-toolkit/latest/python/site-packages/tbe/common/repository_manager/cann_kb_manager/base_manager.py", line 339, in close
    for name in copy.deepcopy(self.write_kb.keys()):
  File "<string>", line 2, in keys
  File "/root/anaconda3/envs/gpt2/lib/python3.10/multiprocessing/managers.py", line 814, in _callmethod
    self._connect()
  File "/root/anaconda3/envs/gpt2/lib/python3.10/multiprocessing/managers.py", line 801, in _connect
    conn = self._Client(self._token.address, authkey=self._authkey)
  File "/root/anaconda3/envs/gpt2/lib/python3.10/multiprocessing/connection.py", line 502, in Client
    c = SocketClient(address)
  File "/root/anaconda3/envs/gpt2/lib/python3.10/multiprocessing/connection.py", line 630, in SocketClient
    s.connect(address)
ConnectionRefusedError: [Errno 111] Connection refused

During handling of the above exception, another exception occurred:

Traceback (most recent call last):
  File "/root/anaconda3/envs/gpt2/lib/python3.10/site-packages/wandb/sdk/lib/redirect.py", line 662, in _on_write
    cb(written_data)
  File "/root/anaconda3/envs/gpt2/lib/python3.10/site-packages/wandb/sdk/wandb_run.py", line 2500, in <lambda>
    lambda data: self._console_raw_callback("stderr", data),
  File "/root/anaconda3/envs/gpt2/lib/python3.10/site-packages/wandb/sdk/wandb_run.py", line 406, in wrapper
    return func(self, *args, **kwargs)
  File "/root/anaconda3/envs/gpt2/lib/python3.10/site-packages/wandb/sdk/wandb_run.py", line 464, in wrapper_fn
    return func(self, *args, **kwargs)
  File "/root/anaconda3/envs/gpt2/lib/python3.10/site-packages/wandb/sdk/wandb_run.py", line 1639, in _console_raw_callback
    self._backend.interface.publish_output_raw(name, data)
  File "/root/anaconda3/envs/gpt2/lib/python3.10/site-packages/wandb/sdk/interface/interface.py", line 762, in publish_output_raw
    self._publish_output_raw(o)
  File "/root/anaconda3/envs/gpt2/lib/python3.10/site-packages/wandb/sdk/interface/interface_shared.py", line 38, in _publish_output_raw
    self._publish(rec)
  File "/root/anaconda3/envs/gpt2/lib/python3.10/site-packages/wandb/sdk/interface/interface_sock.py", line 39, in _publish
    self._sock_client.send_record_publish(record)
  File "/root/anaconda3/envs/gpt2/lib/python3.10/site-packages/wandb/sdk/lib/sock_client.py", line 174, in send_record_publish
    self.send_server_request(server_req)
  File "/root/anaconda3/envs/gpt2/lib/python3.10/site-packages/wandb/sdk/lib/sock_client.py", line 154, in send_server_request
    self._send_message(msg)
  File "/root/anaconda3/envs/gpt2/lib/python3.10/site-packages/wandb/sdk/lib/sock_client.py", line 151, in _send_message
    self._sendall_with_error_handle(header + data)
  File "/root/anaconda3/envs/gpt2/lib/python3.10/site-packages/wandb/sdk/lib/sock_client.py", line 130, in _sendall_with_error_handle
    sent = self._sock.send(data)
BrokenPipeError: [Errno 32] Broken pipe
2025-05-30 17:14:09,637 ERROR   MainThread:1352753 [redirect.py:_on_write():664] [no run ID] error in stderr callback
Traceback (most recent call last):
  File "/root/anaconda3/envs/gpt2/lib/python3.10/multiprocessing/managers.py", line 810, in _callmethod
    conn = self._tls.connection
AttributeError: 'ForkAwareLocal' object has no attribute 'connection'

During handling of the above exception, another exception occurred:

Traceback (most recent call last):
  File "/root/anaconda3/envs/gpt2/lib/python3.10/multiprocessing/util.py", line 300, in _run_finalizers
    finalizer()
  File "/root/anaconda3/envs/gpt2/lib/python3.10/multiprocessing/util.py", line 224, in __call__
    res = self._callback(*self._args, **self._kwargs)
  File "/usr/local/Ascend/ascend-toolkit/latest/python/site-packages/tbe/common/repository_manager/route.py", line 54, in wrapper
    return func(cls, *args, **kwargs)
  File "/usr/local/Ascend/ascend-toolkit/latest/python/site-packages/tbe/common/repository_manager/route.py", line 208, in finalize
    cls.cann_kb_mgr.finalize()
  File "/usr/local/Ascend/ascend-toolkit/latest/python/site-packages/tbe/common/repository_manager/cann_kb_manager/knowledge_bank_manager.py", line 42, in finalize
    self.__static_mgr.close()
  File "/usr/local/Ascend/ascend-toolkit/latest/python/site-packages/tbe/common/repository_manager/cann_kb_manager/base_manager.py", line 339, in close
    for name in copy.deepcopy(self.write_kb.keys()):
  File "<string>", line 2, in keys
  File "/root/anaconda3/envs/gpt2/lib/python3.10/multiprocessing/managers.py", line 814, in _callmethod
    self._connect()
  File "/root/anaconda3/envs/gpt2/lib/python3.10/multiprocessing/managers.py", line 801, in _connect
    conn = self._Client(self._token.address, authkey=self._authkey)
  File "/root/anaconda3/envs/gpt2/lib/python3.10/multiprocessing/connection.py", line 502, in Client
    c = SocketClient(address)
  File "/root/anaconda3/envs/gpt2/lib/python3.10/multiprocessing/connection.py", line 630, in SocketClient
    s.connect(address)
ConnectionRefusedError: [Errno 111] Connection refused

During handling of the above exception, another exception occurred:

Traceback (most recent call last):
  File "/root/anaconda3/envs/gpt2/lib/python3.10/site-packages/wandb/sdk/lib/redirect.py", line 662, in _on_write
    cb(written_data)
  File "/root/anaconda3/envs/gpt2/lib/python3.10/site-packages/wandb/sdk/wandb_run.py", line 2500, in <lambda>
    lambda data: self._console_raw_callback("stderr", data),
  File "/root/anaconda3/envs/gpt2/lib/python3.10/site-packages/wandb/sdk/wandb_run.py", line 406, in wrapper
    return func(self, *args, **kwargs)
  File "/root/anaconda3/envs/gpt2/lib/python3.10/site-packages/wandb/sdk/wandb_run.py", line 464, in wrapper_fn
    return func(self, *args, **kwargs)
  File "/root/anaconda3/envs/gpt2/lib/python3.10/site-packages/wandb/sdk/wandb_run.py", line 1639, in _console_raw_callback
    self._backend.interface.publish_output_raw(name, data)
  File "/root/anaconda3/envs/gpt2/lib/python3.10/site-packages/wandb/sdk/interface/interface.py", line 762, in publish_output_raw
    self._publish_output_raw(o)
  File "/root/anaconda3/envs/gpt2/lib/python3.10/site-packages/wandb/sdk/interface/interface_shared.py", line 38, in _publish_output_raw
    self._publish(rec)
  File "/root/anaconda3/envs/gpt2/lib/python3.10/site-packages/wandb/sdk/interface/interface_sock.py", line 39, in _publish
    self._sock_client.send_record_publish(record)
  File "/root/anaconda3/envs/gpt2/lib/python3.10/site-packages/wandb/sdk/lib/sock_client.py", line 174, in send_record_publish
    self.send_server_request(server_req)
  File "/root/anaconda3/envs/gpt2/lib/python3.10/site-packages/wandb/sdk/lib/sock_client.py", line 154, in send_server_request
    self._send_message(msg)
  File "/root/anaconda3/envs/gpt2/lib/python3.10/site-packages/wandb/sdk/lib/sock_client.py", line 151, in _send_message
    self._sendall_with_error_handle(header + data)
  File "/root/anaconda3/envs/gpt2/lib/python3.10/site-packages/wandb/sdk/lib/sock_client.py", line 130, in _sendall_with_error_handle
    sent = self._sock.send(data)
BrokenPipeError: [Errno 32] Broken pipe
2025-05-30 17:14:09,638 ERROR   MainThread:1352753 [redirect.py:_on_write():664] [no run ID] error in stderr callback
Traceback (most recent call last):
  File "/root/anaconda3/envs/gpt2/lib/python3.10/multiprocessing/managers.py", line 810, in _callmethod
    conn = self._tls.connection
AttributeError: 'ForkAwareLocal' object has no attribute 'connection'

During handling of the above exception, another exception occurred:

Traceback (most recent call last):
  File "/root/anaconda3/envs/gpt2/lib/python3.10/multiprocessing/util.py", line 300, in _run_finalizers
    finalizer()
  File "/root/anaconda3/envs/gpt2/lib/python3.10/multiprocessing/util.py", line 224, in __call__
    res = self._callback(*self._args, **self._kwargs)
  File "/usr/local/Ascend/ascend-toolkit/latest/python/site-packages/tbe/common/repository_manager/route.py", line 54, in wrapper
    return func(cls, *args, **kwargs)
  File "/usr/local/Ascend/ascend-toolkit/latest/python/site-packages/tbe/common/repository_manager/route.py", line 208, in finalize
    cls.cann_kb_mgr.finalize()
  File "/usr/local/Ascend/ascend-toolkit/latest/python/site-packages/tbe/common/repository_manager/cann_kb_manager/knowledge_bank_manager.py", line 42, in finalize
    self.__static_mgr.close()
  File "/usr/local/Ascend/ascend-toolkit/latest/python/site-packages/tbe/common/repository_manager/cann_kb_manager/base_manager.py", line 339, in close
    for name in copy.deepcopy(self.write_kb.keys()):
  File "<string>", line 2, in keys
  File "/root/anaconda3/envs/gpt2/lib/python3.10/multiprocessing/managers.py", line 814, in _callmethod
    self._connect()
  File "/root/anaconda3/envs/gpt2/lib/python3.10/multiprocessing/managers.py", line 801, in _connect
    conn = self._Client(self._token.address, authkey=self._authkey)
  File "/root/anaconda3/envs/gpt2/lib/python3.10/multiprocessing/connection.py", line 502, in Client
    c = SocketClient(address)
  File "/root/anaconda3/envs/gpt2/lib/python3.10/multiprocessing/connection.py", line 630, in SocketClient
    s.connect(address)
ConnectionRefusedError: [Errno 111] Connection refused

During handling of the above exception, another exception occurred:

Traceback (most recent call last):
  File "/root/anaconda3/envs/gpt2/lib/python3.10/site-packages/wandb/sdk/lib/redirect.py", line 662, in _on_write
    cb(written_data)
  File "/root/anaconda3/envs/gpt2/lib/python3.10/site-packages/wandb/sdk/wandb_run.py", line 2500, in <lambda>
    lambda data: self._console_raw_callback("stderr", data),
  File "/root/anaconda3/envs/gpt2/lib/python3.10/site-packages/wandb/sdk/wandb_run.py", line 406, in wrapper
    return func(self, *args, **kwargs)
  File "/root/anaconda3/envs/gpt2/lib/python3.10/site-packages/wandb/sdk/wandb_run.py", line 464, in wrapper_fn
    return func(self, *args, **kwargs)
  File "/root/anaconda3/envs/gpt2/lib/python3.10/site-packages/wandb/sdk/wandb_run.py", line 1639, in _console_raw_callback
    self._backend.interface.publish_output_raw(name, data)
  File "/root/anaconda3/envs/gpt2/lib/python3.10/site-packages/wandb/sdk/interface/interface.py", line 762, in publish_output_raw
    self._publish_output_raw(o)
  File "/root/anaconda3/envs/gpt2/lib/python3.10/site-packages/wandb/sdk/interface/interface_shared.py", line 38, in _publish_output_raw
    self._publish(rec)
  File "/root/anaconda3/envs/gpt2/lib/python3.10/site-packages/wandb/sdk/interface/interface_sock.py", line 39, in _publish
    self._sock_client.send_record_publish(record)
  File "/root/anaconda3/envs/gpt2/lib/python3.10/site-packages/wandb/sdk/lib/sock_client.py", line 174, in send_record_publish
    self.send_server_request(server_req)
  File "/root/anaconda3/envs/gpt2/lib/python3.10/site-packages/wandb/sdk/lib/sock_client.py", line 154, in send_server_request
    self._send_message(msg)
  File "/root/anaconda3/envs/gpt2/lib/python3.10/site-packages/wandb/sdk/lib/sock_client.py", line 151, in _send_message
    self._sendall_with_error_handle(header + data)
  File "/root/anaconda3/envs/gpt2/lib/python3.10/site-packages/wandb/sdk/lib/sock_client.py", line 130, in _sendall_with_error_handle
    sent = self._sock.send(data)
BrokenPipeError: [Errno 32] Broken pipe
2025-05-30 17:14:09,638 ERROR   MainThread:1352753 [redirect.py:_on_write():664] [no run ID] error in stderr callback
Traceback (most recent call last):
  File "/root/anaconda3/envs/gpt2/lib/python3.10/multiprocessing/managers.py", line 810, in _callmethod
    conn = self._tls.connection
AttributeError: 'ForkAwareLocal' object has no attribute 'connection'

During handling of the above exception, another exception occurred:

Traceback (most recent call last):
  File "/root/anaconda3/envs/gpt2/lib/python3.10/multiprocessing/util.py", line 300, in _run_finalizers
    finalizer()
  File "/root/anaconda3/envs/gpt2/lib/python3.10/multiprocessing/util.py", line 224, in __call__
    res = self._callback(*self._args, **self._kwargs)
  File "/usr/local/Ascend/ascend-toolkit/latest/python/site-packages/tbe/common/repository_manager/route.py", line 54, in wrapper
    return func(cls, *args, **kwargs)
  File "/usr/local/Ascend/ascend-toolkit/latest/python/site-packages/tbe/common/repository_manager/route.py", line 208, in finalize
    cls.cann_kb_mgr.finalize()
  File "/usr/local/Ascend/ascend-toolkit/latest/python/site-packages/tbe/common/repository_manager/cann_kb_manager/knowledge_bank_manager.py", line 42, in finalize
    self.__static_mgr.close()
  File "/usr/local/Ascend/ascend-toolkit/latest/python/site-packages/tbe/common/repository_manager/cann_kb_manager/base_manager.py", line 339, in close
    for name in copy.deepcopy(self.write_kb.keys()):
  File "<string>", line 2, in keys
  File "/root/anaconda3/envs/gpt2/lib/python3.10/multiprocessing/managers.py", line 814, in _callmethod
    self._connect()
  File "/root/anaconda3/envs/gpt2/lib/python3.10/multiprocessing/managers.py", line 801, in _connect
    conn = self._Client(self._token.address, authkey=self._authkey)
  File "/root/anaconda3/envs/gpt2/lib/python3.10/multiprocessing/connection.py", line 502, in Client
    c = SocketClient(address)
  File "/root/anaconda3/envs/gpt2/lib/python3.10/multiprocessing/connection.py", line 630, in SocketClient
    s.connect(address)
ConnectionRefusedError: [Errno 111] Connection refused

During handling of the above exception, another exception occurred:

Traceback (most recent call last):
  File "/root/anaconda3/envs/gpt2/lib/python3.10/site-packages/wandb/sdk/lib/redirect.py", line 662, in _on_write
    cb(written_data)
  File "/root/anaconda3/envs/gpt2/lib/python3.10/site-packages/wandb/sdk/wandb_run.py", line 2500, in <lambda>
    lambda data: self._console_raw_callback("stderr", data),
  File "/root/anaconda3/envs/gpt2/lib/python3.10/site-packages/wandb/sdk/wandb_run.py", line 406, in wrapper
    return func(self, *args, **kwargs)
  File "/root/anaconda3/envs/gpt2/lib/python3.10/site-packages/wandb/sdk/wandb_run.py", line 464, in wrapper_fn
    return func(self, *args, **kwargs)
  File "/root/anaconda3/envs/gpt2/lib/python3.10/site-packages/wandb/sdk/wandb_run.py", line 1639, in _console_raw_callback
    self._backend.interface.publish_output_raw(name, data)
  File "/root/anaconda3/envs/gpt2/lib/python3.10/site-packages/wandb/sdk/interface/interface.py", line 762, in publish_output_raw
    self._publish_output_raw(o)
  File "/root/anaconda3/envs/gpt2/lib/python3.10/site-packages/wandb/sdk/interface/interface_shared.py", line 38, in _publish_output_raw
    self._publish(rec)
  File "/root/anaconda3/envs/gpt2/lib/python3.10/site-packages/wandb/sdk/interface/interface_sock.py", line 39, in _publish
    self._sock_client.send_record_publish(record)
  File "/root/anaconda3/envs/gpt2/lib/python3.10/site-packages/wandb/sdk/lib/sock_client.py", line 174, in send_record_publish
    self.send_server_request(server_req)
  File "/root/anaconda3/envs/gpt2/lib/python3.10/site-packages/wandb/sdk/lib/sock_client.py", line 154, in send_server_request
    self._send_message(msg)
  File "/root/anaconda3/envs/gpt2/lib/python3.10/site-packages/wandb/sdk/lib/sock_client.py", line 151, in _send_message
    self._sendall_with_error_handle(header + data)
  File "/root/anaconda3/envs/gpt2/lib/python3.10/site-packages/wandb/sdk/lib/sock_client.py", line 130, in _sendall_with_error_handle
    sent = self._sock.send(data)
BrokenPipeError: [Errno 32] Broken pipe
2025-05-30 17:14:09,639 ERROR   MainThread:1352753 [redirect.py:_on_write():664] [no run ID] error in stderr callback
Traceback (most recent call last):
  File "/root/anaconda3/envs/gpt2/lib/python3.10/multiprocessing/managers.py", line 810, in _callmethod
    conn = self._tls.connection
AttributeError: 'ForkAwareLocal' object has no attribute 'connection'

During handling of the above exception, another exception occurred:

Traceback (most recent call last):
  File "/root/anaconda3/envs/gpt2/lib/python3.10/multiprocessing/util.py", line 300, in _run_finalizers
    finalizer()
  File "/root/anaconda3/envs/gpt2/lib/python3.10/multiprocessing/util.py", line 224, in __call__
    res = self._callback(*self._args, **self._kwargs)
  File "/usr/local/Ascend/ascend-toolkit/latest/python/site-packages/tbe/common/repository_manager/route.py", line 54, in wrapper
    return func(cls, *args, **kwargs)
  File "/usr/local/Ascend/ascend-toolkit/latest/python/site-packages/tbe/common/repository_manager/route.py", line 208, in finalize
    cls.cann_kb_mgr.finalize()
  File "/usr/local/Ascend/ascend-toolkit/latest/python/site-packages/tbe/common/repository_manager/cann_kb_manager/knowledge_bank_manager.py", line 42, in finalize
    self.__static_mgr.close()
  File "/usr/local/Ascend/ascend-toolkit/latest/python/site-packages/tbe/common/repository_manager/cann_kb_manager/base_manager.py", line 339, in close
    for name in copy.deepcopy(self.write_kb.keys()):
  File "<string>", line 2, in keys
  File "/root/anaconda3/envs/gpt2/lib/python3.10/multiprocessing/managers.py", line 814, in _callmethod
    self._connect()
  File "/root/anaconda3/envs/gpt2/lib/python3.10/multiprocessing/managers.py", line 801, in _connect
    conn = self._Client(self._token.address, authkey=self._authkey)
  File "/root/anaconda3/envs/gpt2/lib/python3.10/multiprocessing/connection.py", line 502, in Client
    c = SocketClient(address)
  File "/root/anaconda3/envs/gpt2/lib/python3.10/multiprocessing/connection.py", line 630, in SocketClient
    s.connect(address)
ConnectionRefusedError: [Errno 111] Connection refused

During handling of the above exception, another exception occurred:

Traceback (most recent call last):
  File "/root/anaconda3/envs/gpt2/lib/python3.10/site-packages/wandb/sdk/lib/redirect.py", line 662, in _on_write
    cb(written_data)
  File "/root/anaconda3/envs/gpt2/lib/python3.10/site-packages/wandb/sdk/wandb_run.py", line 2500, in <lambda>
    lambda data: self._console_raw_callback("stderr", data),
  File "/root/anaconda3/envs/gpt2/lib/python3.10/site-packages/wandb/sdk/wandb_run.py", line 406, in wrapper
    return func(self, *args, **kwargs)
  File "/root/anaconda3/envs/gpt2/lib/python3.10/site-packages/wandb/sdk/wandb_run.py", line 464, in wrapper_fn
    return func(self, *args, **kwargs)
  File "/root/anaconda3/envs/gpt2/lib/python3.10/site-packages/wandb/sdk/wandb_run.py", line 1639, in _console_raw_callback
    self._backend.interface.publish_output_raw(name, data)
  File "/root/anaconda3/envs/gpt2/lib/python3.10/site-packages/wandb/sdk/interface/interface.py", line 762, in publish_output_raw
    self._publish_output_raw(o)
  File "/root/anaconda3/envs/gpt2/lib/python3.10/site-packages/wandb/sdk/interface/interface_shared.py", line 38, in _publish_output_raw
    self._publish(rec)
  File "/root/anaconda3/envs/gpt2/lib/python3.10/site-packages/wandb/sdk/interface/interface_sock.py", line 39, in _publish
    self._sock_client.send_record_publish(record)
  File "/root/anaconda3/envs/gpt2/lib/python3.10/site-packages/wandb/sdk/lib/sock_client.py", line 174, in send_record_publish
    self.send_server_request(server_req)
  File "/root/anaconda3/envs/gpt2/lib/python3.10/site-packages/wandb/sdk/lib/sock_client.py", line 154, in send_server_request
    self._send_message(msg)
  File "/root/anaconda3/envs/gpt2/lib/python3.10/site-packages/wandb/sdk/lib/sock_client.py", line 151, in _send_message
    self._sendall_with_error_handle(header + data)
  File "/root/anaconda3/envs/gpt2/lib/python3.10/site-packages/wandb/sdk/lib/sock_client.py", line 130, in _sendall_with_error_handle
    sent = self._sock.send(data)
BrokenPipeError: [Errno 32] Broken pipe
2025-05-30 17:14:09,640 ERROR   MainThread:1352753 [redirect.py:_on_write():664] [no run ID] error in stderr callback
Traceback (most recent call last):
  File "/root/anaconda3/envs/gpt2/lib/python3.10/multiprocessing/managers.py", line 810, in _callmethod
    conn = self._tls.connection
AttributeError: 'ForkAwareLocal' object has no attribute 'connection'

During handling of the above exception, another exception occurred:

Traceback (most recent call last):
  File "/root/anaconda3/envs/gpt2/lib/python3.10/multiprocessing/util.py", line 300, in _run_finalizers
    finalizer()
  File "/root/anaconda3/envs/gpt2/lib/python3.10/multiprocessing/util.py", line 224, in __call__
    res = self._callback(*self._args, **self._kwargs)
  File "/usr/local/Ascend/ascend-toolkit/latest/python/site-packages/tbe/common/repository_manager/route.py", line 54, in wrapper
    return func(cls, *args, **kwargs)
  File "/usr/local/Ascend/ascend-toolkit/latest/python/site-packages/tbe/common/repository_manager/route.py", line 208, in finalize
    cls.cann_kb_mgr.finalize()
  File "/usr/local/Ascend/ascend-toolkit/latest/python/site-packages/tbe/common/repository_manager/cann_kb_manager/knowledge_bank_manager.py", line 42, in finalize
    self.__static_mgr.close()
  File "/usr/local/Ascend/ascend-toolkit/latest/python/site-packages/tbe/common/repository_manager/cann_kb_manager/base_manager.py", line 339, in close
    for name in copy.deepcopy(self.write_kb.keys()):
  File "<string>", line 2, in keys
  File "/root/anaconda3/envs/gpt2/lib/python3.10/multiprocessing/managers.py", line 814, in _callmethod
    self._connect()
  File "/root/anaconda3/envs/gpt2/lib/python3.10/multiprocessing/managers.py", line 801, in _connect
    conn = self._Client(self._token.address, authkey=self._authkey)
  File "/root/anaconda3/envs/gpt2/lib/python3.10/multiprocessing/connection.py", line 502, in Client
    c = SocketClient(address)
  File "/root/anaconda3/envs/gpt2/lib/python3.10/multiprocessing/connection.py", line 630, in SocketClient
    s.connect(address)
ConnectionRefusedError: [Errno 111] Connection refused

During handling of the above exception, another exception occurred:

Traceback (most recent call last):
  File "/root/anaconda3/envs/gpt2/lib/python3.10/site-packages/wandb/sdk/lib/redirect.py", line 662, in _on_write
    cb(written_data)
  File "/root/anaconda3/envs/gpt2/lib/python3.10/site-packages/wandb/sdk/wandb_run.py", line 2500, in <lambda>
    lambda data: self._console_raw_callback("stderr", data),
  File "/root/anaconda3/envs/gpt2/lib/python3.10/site-packages/wandb/sdk/wandb_run.py", line 406, in wrapper
    return func(self, *args, **kwargs)
  File "/root/anaconda3/envs/gpt2/lib/python3.10/site-packages/wandb/sdk/wandb_run.py", line 464, in wrapper_fn
    return func(self, *args, **kwargs)
  File "/root/anaconda3/envs/gpt2/lib/python3.10/site-packages/wandb/sdk/wandb_run.py", line 1639, in _console_raw_callback
    self._backend.interface.publish_output_raw(name, data)
  File "/root/anaconda3/envs/gpt2/lib/python3.10/site-packages/wandb/sdk/interface/interface.py", line 762, in publish_output_raw
    self._publish_output_raw(o)
  File "/root/anaconda3/envs/gpt2/lib/python3.10/site-packages/wandb/sdk/interface/interface_shared.py", line 38, in _publish_output_raw
    self._publish(rec)
  File "/root/anaconda3/envs/gpt2/lib/python3.10/site-packages/wandb/sdk/interface/interface_sock.py", line 39, in _publish
    self._sock_client.send_record_publish(record)
  File "/root/anaconda3/envs/gpt2/lib/python3.10/site-packages/wandb/sdk/lib/sock_client.py", line 174, in send_record_publish
    self.send_server_request(server_req)
  File "/root/anaconda3/envs/gpt2/lib/python3.10/site-packages/wandb/sdk/lib/sock_client.py", line 154, in send_server_request
    self._send_message(msg)
  File "/root/anaconda3/envs/gpt2/lib/python3.10/site-packages/wandb/sdk/lib/sock_client.py", line 151, in _send_message
    self._sendall_with_error_handle(header + data)
  File "/root/anaconda3/envs/gpt2/lib/python3.10/site-packages/wandb/sdk/lib/sock_client.py", line 130, in _sendall_with_error_handle
    sent = self._sock.send(data)
BrokenPipeError: [Errno 32] Broken pipe
2025-05-30 17:14:09,640 ERROR   MainThread:1352753 [redirect.py:_on_write():664] [no run ID] error in stderr callback
Traceback (most recent call last):
  File "/root/anaconda3/envs/gpt2/lib/python3.10/multiprocessing/managers.py", line 810, in _callmethod
    conn = self._tls.connection
AttributeError: 'ForkAwareLocal' object has no attribute 'connection'

During handling of the above exception, another exception occurred:

Traceback (most recent call last):
  File "/root/anaconda3/envs/gpt2/lib/python3.10/multiprocessing/util.py", line 300, in _run_finalizers
    finalizer()
  File "/root/anaconda3/envs/gpt2/lib/python3.10/multiprocessing/util.py", line 224, in __call__
    res = self._callback(*self._args, **self._kwargs)
  File "/usr/local/Ascend/ascend-toolkit/latest/python/site-packages/tbe/common/repository_manager/route.py", line 54, in wrapper
    return func(cls, *args, **kwargs)
  File "/usr/local/Ascend/ascend-toolkit/latest/python/site-packages/tbe/common/repository_manager/route.py", line 208, in finalize
    cls.cann_kb_mgr.finalize()
  File "/usr/local/Ascend/ascend-toolkit/latest/python/site-packages/tbe/common/repository_manager/cann_kb_manager/knowledge_bank_manager.py", line 42, in finalize
    self.__static_mgr.close()
  File "/usr/local/Ascend/ascend-toolkit/latest/python/site-packages/tbe/common/repository_manager/cann_kb_manager/base_manager.py", line 339, in close
    for name in copy.deepcopy(self.write_kb.keys()):
  File "<string>", line 2, in keys
  File "/root/anaconda3/envs/gpt2/lib/python3.10/multiprocessing/managers.py", line 814, in _callmethod
    self._connect()
  File "/root/anaconda3/envs/gpt2/lib/python3.10/multiprocessing/managers.py", line 801, in _connect
    conn = self._Client(self._token.address, authkey=self._authkey)
  File "/root/anaconda3/envs/gpt2/lib/python3.10/multiprocessing/connection.py", line 502, in Client
    c = SocketClient(address)
  File "/root/anaconda3/envs/gpt2/lib/python3.10/multiprocessing/connection.py", line 630, in SocketClient
    s.connect(address)
ConnectionRefusedError: [Errno 111] Connection refused

During handling of the above exception, another exception occurred:

Traceback (most recent call last):
  File "/root/anaconda3/envs/gpt2/lib/python3.10/site-packages/wandb/sdk/lib/redirect.py", line 662, in _on_write
    cb(written_data)
  File "/root/anaconda3/envs/gpt2/lib/python3.10/site-packages/wandb/sdk/wandb_run.py", line 2500, in <lambda>
    lambda data: self._console_raw_callback("stderr", data),
  File "/root/anaconda3/envs/gpt2/lib/python3.10/site-packages/wandb/sdk/wandb_run.py", line 406, in wrapper
    return func(self, *args, **kwargs)
  File "/root/anaconda3/envs/gpt2/lib/python3.10/site-packages/wandb/sdk/wandb_run.py", line 464, in wrapper_fn
    return func(self, *args, **kwargs)
  File "/root/anaconda3/envs/gpt2/lib/python3.10/site-packages/wandb/sdk/wandb_run.py", line 1639, in _console_raw_callback
    self._backend.interface.publish_output_raw(name, data)
  File "/root/anaconda3/envs/gpt2/lib/python3.10/site-packages/wandb/sdk/interface/interface.py", line 762, in publish_output_raw
    self._publish_output_raw(o)
  File "/root/anaconda3/envs/gpt2/lib/python3.10/site-packages/wandb/sdk/interface/interface_shared.py", line 38, in _publish_output_raw
    self._publish(rec)
  File "/root/anaconda3/envs/gpt2/lib/python3.10/site-packages/wandb/sdk/interface/interface_sock.py", line 39, in _publish
    self._sock_client.send_record_publish(record)
  File "/root/anaconda3/envs/gpt2/lib/python3.10/site-packages/wandb/sdk/lib/sock_client.py", line 174, in send_record_publish
    self.send_server_request(server_req)
  File "/root/anaconda3/envs/gpt2/lib/python3.10/site-packages/wandb/sdk/lib/sock_client.py", line 154, in send_server_request
    self._send_message(msg)
  File "/root/anaconda3/envs/gpt2/lib/python3.10/site-packages/wandb/sdk/lib/sock_client.py", line 151, in _send_message
    self._sendall_with_error_handle(header + data)
  File "/root/anaconda3/envs/gpt2/lib/python3.10/site-packages/wandb/sdk/lib/sock_client.py", line 130, in _sendall_with_error_handle
    sent = self._sock.send(data)
BrokenPipeError: [Errno 32] Broken pipe
2025-05-30 17:14:09,641 ERROR   MainThread:1352753 [redirect.py:_on_write():664] [no run ID] error in stderr callback
Traceback (most recent call last):
  File "/root/anaconda3/envs/gpt2/lib/python3.10/multiprocessing/managers.py", line 810, in _callmethod
    conn = self._tls.connection
AttributeError: 'ForkAwareLocal' object has no attribute 'connection'

During handling of the above exception, another exception occurred:

Traceback (most recent call last):
  File "/root/anaconda3/envs/gpt2/lib/python3.10/multiprocessing/util.py", line 300, in _run_finalizers
    finalizer()
  File "/root/anaconda3/envs/gpt2/lib/python3.10/multiprocessing/util.py", line 224, in __call__
    res = self._callback(*self._args, **self._kwargs)
  File "/usr/local/Ascend/ascend-toolkit/latest/python/site-packages/tbe/common/repository_manager/route.py", line 54, in wrapper
    return func(cls, *args, **kwargs)
  File "/usr/local/Ascend/ascend-toolkit/latest/python/site-packages/tbe/common/repository_manager/route.py", line 208, in finalize
    cls.cann_kb_mgr.finalize()
  File "/usr/local/Ascend/ascend-toolkit/latest/python/site-packages/tbe/common/repository_manager/cann_kb_manager/knowledge_bank_manager.py", line 42, in finalize
    self.__static_mgr.close()
  File "/usr/local/Ascend/ascend-toolkit/latest/python/site-packages/tbe/common/repository_manager/cann_kb_manager/base_manager.py", line 339, in close
    for name in copy.deepcopy(self.write_kb.keys()):
  File "<string>", line 2, in keys
  File "/root/anaconda3/envs/gpt2/lib/python3.10/multiprocessing/managers.py", line 814, in _callmethod
    self._connect()
  File "/root/anaconda3/envs/gpt2/lib/python3.10/multiprocessing/managers.py", line 801, in _connect
    conn = self._Client(self._token.address, authkey=self._authkey)
  File "/root/anaconda3/envs/gpt2/lib/python3.10/multiprocessing/connection.py", line 502, in Client
    c = SocketClient(address)
  File "/root/anaconda3/envs/gpt2/lib/python3.10/multiprocessing/connection.py", line 630, in SocketClient
    s.connect(address)
ConnectionRefusedError: [Errno 111] Connection refused

During handling of the above exception, another exception occurred:

Traceback (most recent call last):
  File "/root/anaconda3/envs/gpt2/lib/python3.10/site-packages/wandb/sdk/lib/redirect.py", line 662, in _on_write
    cb(written_data)
  File "/root/anaconda3/envs/gpt2/lib/python3.10/site-packages/wandb/sdk/wandb_run.py", line 2500, in <lambda>
    lambda data: self._console_raw_callback("stderr", data),
  File "/root/anaconda3/envs/gpt2/lib/python3.10/site-packages/wandb/sdk/wandb_run.py", line 406, in wrapper
    return func(self, *args, **kwargs)
  File "/root/anaconda3/envs/gpt2/lib/python3.10/site-packages/wandb/sdk/wandb_run.py", line 464, in wrapper_fn
    return func(self, *args, **kwargs)
  File "/root/anaconda3/envs/gpt2/lib/python3.10/site-packages/wandb/sdk/wandb_run.py", line 1639, in _console_raw_callback
    self._backend.interface.publish_output_raw(name, data)
  File "/root/anaconda3/envs/gpt2/lib/python3.10/site-packages/wandb/sdk/interface/interface.py", line 762, in publish_output_raw
    self._publish_output_raw(o)
  File "/root/anaconda3/envs/gpt2/lib/python3.10/site-packages/wandb/sdk/interface/interface_shared.py", line 38, in _publish_output_raw
    self._publish(rec)
  File "/root/anaconda3/envs/gpt2/lib/python3.10/site-packages/wandb/sdk/interface/interface_sock.py", line 39, in _publish
    self._sock_client.send_record_publish(record)
  File "/root/anaconda3/envs/gpt2/lib/python3.10/site-packages/wandb/sdk/lib/sock_client.py", line 174, in send_record_publish
    self.send_server_request(server_req)
  File "/root/anaconda3/envs/gpt2/lib/python3.10/site-packages/wandb/sdk/lib/sock_client.py", line 154, in send_server_request
    self._send_message(msg)
  File "/root/anaconda3/envs/gpt2/lib/python3.10/site-packages/wandb/sdk/lib/sock_client.py", line 151, in _send_message
    self._sendall_with_error_handle(header + data)
  File "/root/anaconda3/envs/gpt2/lib/python3.10/site-packages/wandb/sdk/lib/sock_client.py", line 130, in _sendall_with_error_handle
    sent = self._sock.send(data)
BrokenPipeError: [Errno 32] Broken pipe
2025-05-30 17:14:09,641 ERROR   MainThread:1352753 [redirect.py:_on_write():664] [no run ID] error in stderr callback
Traceback (most recent call last):
  File "/root/anaconda3/envs/gpt2/lib/python3.10/multiprocessing/managers.py", line 810, in _callmethod
    conn = self._tls.connection
AttributeError: 'ForkAwareLocal' object has no attribute 'connection'

During handling of the above exception, another exception occurred:

Traceback (most recent call last):
  File "/root/anaconda3/envs/gpt2/lib/python3.10/multiprocessing/util.py", line 300, in _run_finalizers
    finalizer()
  File "/root/anaconda3/envs/gpt2/lib/python3.10/multiprocessing/util.py", line 224, in __call__
    res = self._callback(*self._args, **self._kwargs)
  File "/usr/local/Ascend/ascend-toolkit/latest/python/site-packages/tbe/common/repository_manager/route.py", line 54, in wrapper
    return func(cls, *args, **kwargs)
  File "/usr/local/Ascend/ascend-toolkit/latest/python/site-packages/tbe/common/repository_manager/route.py", line 208, in finalize
    cls.cann_kb_mgr.finalize()
  File "/usr/local/Ascend/ascend-toolkit/latest/python/site-packages/tbe/common/repository_manager/cann_kb_manager/knowledge_bank_manager.py", line 42, in finalize
    self.__static_mgr.close()
  File "/usr/local/Ascend/ascend-toolkit/latest/python/site-packages/tbe/common/repository_manager/cann_kb_manager/base_manager.py", line 339, in close
    for name in copy.deepcopy(self.write_kb.keys()):
  File "<string>", line 2, in keys
  File "/root/anaconda3/envs/gpt2/lib/python3.10/multiprocessing/managers.py", line 814, in _callmethod
    self._connect()
  File "/root/anaconda3/envs/gpt2/lib/python3.10/multiprocessing/managers.py", line 801, in _connect
    conn = self._Client(self._token.address, authkey=self._authkey)
  File "/root/anaconda3/envs/gpt2/lib/python3.10/multiprocessing/connection.py", line 502, in Client
    c = SocketClient(address)
  File "/root/anaconda3/envs/gpt2/lib/python3.10/multiprocessing/connection.py", line 630, in SocketClient
    s.connect(address)
ConnectionRefusedError: [Errno 111] Connection refused

During handling of the above exception, another exception occurred:

Traceback (most recent call last):
  File "/root/anaconda3/envs/gpt2/lib/python3.10/site-packages/wandb/sdk/lib/redirect.py", line 662, in _on_write
    cb(written_data)
  File "/root/anaconda3/envs/gpt2/lib/python3.10/site-packages/wandb/sdk/wandb_run.py", line 2500, in <lambda>
    lambda data: self._console_raw_callback("stderr", data),
  File "/root/anaconda3/envs/gpt2/lib/python3.10/site-packages/wandb/sdk/wandb_run.py", line 406, in wrapper
    return func(self, *args, **kwargs)
  File "/root/anaconda3/envs/gpt2/lib/python3.10/site-packages/wandb/sdk/wandb_run.py", line 464, in wrapper_fn
    return func(self, *args, **kwargs)
  File "/root/anaconda3/envs/gpt2/lib/python3.10/site-packages/wandb/sdk/wandb_run.py", line 1639, in _console_raw_callback
    self._backend.interface.publish_output_raw(name, data)
  File "/root/anaconda3/envs/gpt2/lib/python3.10/site-packages/wandb/sdk/interface/interface.py", line 762, in publish_output_raw
    self._publish_output_raw(o)
  File "/root/anaconda3/envs/gpt2/lib/python3.10/site-packages/wandb/sdk/interface/interface_shared.py", line 38, in _publish_output_raw
    self._publish(rec)
  File "/root/anaconda3/envs/gpt2/lib/python3.10/site-packages/wandb/sdk/interface/interface_sock.py", line 39, in _publish
    self._sock_client.send_record_publish(record)
  File "/root/anaconda3/envs/gpt2/lib/python3.10/site-packages/wandb/sdk/lib/sock_client.py", line 174, in send_record_publish
    self.send_server_request(server_req)
  File "/root/anaconda3/envs/gpt2/lib/python3.10/site-packages/wandb/sdk/lib/sock_client.py", line 154, in send_server_request
    self._send_message(msg)
  File "/root/anaconda3/envs/gpt2/lib/python3.10/site-packages/wandb/sdk/lib/sock_client.py", line 151, in _send_message
    self._sendall_with_error_handle(header + data)
  File "/root/anaconda3/envs/gpt2/lib/python3.10/site-packages/wandb/sdk/lib/sock_client.py", line 130, in _sendall_with_error_handle
    sent = self._sock.send(data)
BrokenPipeError: [Errno 32] Broken pipe
2025-05-30 17:14:09,642 ERROR   MainThread:1352753 [redirect.py:_on_write():664] [no run ID] error in stderr callback
Traceback (most recent call last):
  File "/root/anaconda3/envs/gpt2/lib/python3.10/multiprocessing/managers.py", line 810, in _callmethod
    conn = self._tls.connection
AttributeError: 'ForkAwareLocal' object has no attribute 'connection'

During handling of the above exception, another exception occurred:

Traceback (most recent call last):
  File "/root/anaconda3/envs/gpt2/lib/python3.10/multiprocessing/util.py", line 300, in _run_finalizers
    finalizer()
  File "/root/anaconda3/envs/gpt2/lib/python3.10/multiprocessing/util.py", line 224, in __call__
    res = self._callback(*self._args, **self._kwargs)
  File "/usr/local/Ascend/ascend-toolkit/latest/python/site-packages/tbe/common/repository_manager/route.py", line 54, in wrapper
    return func(cls, *args, **kwargs)
  File "/usr/local/Ascend/ascend-toolkit/latest/python/site-packages/tbe/common/repository_manager/route.py", line 208, in finalize
    cls.cann_kb_mgr.finalize()
  File "/usr/local/Ascend/ascend-toolkit/latest/python/site-packages/tbe/common/repository_manager/cann_kb_manager/knowledge_bank_manager.py", line 42, in finalize
    self.__static_mgr.close()
  File "/usr/local/Ascend/ascend-toolkit/latest/python/site-packages/tbe/common/repository_manager/cann_kb_manager/base_manager.py", line 339, in close
    for name in copy.deepcopy(self.write_kb.keys()):
  File "<string>", line 2, in keys
  File "/root/anaconda3/envs/gpt2/lib/python3.10/multiprocessing/managers.py", line 814, in _callmethod
    self._connect()
  File "/root/anaconda3/envs/gpt2/lib/python3.10/multiprocessing/managers.py", line 801, in _connect
    conn = self._Client(self._token.address, authkey=self._authkey)
  File "/root/anaconda3/envs/gpt2/lib/python3.10/multiprocessing/connection.py", line 502, in Client
    c = SocketClient(address)
  File "/root/anaconda3/envs/gpt2/lib/python3.10/multiprocessing/connection.py", line 630, in SocketClient
    s.connect(address)
ConnectionRefusedError: [Errno 111] Connection refused

During handling of the above exception, another exception occurred:

Traceback (most recent call last):
  File "/root/anaconda3/envs/gpt2/lib/python3.10/site-packages/wandb/sdk/lib/redirect.py", line 662, in _on_write
    cb(written_data)
  File "/root/anaconda3/envs/gpt2/lib/python3.10/site-packages/wandb/sdk/wandb_run.py", line 2500, in <lambda>
    lambda data: self._console_raw_callback("stderr", data),
  File "/root/anaconda3/envs/gpt2/lib/python3.10/site-packages/wandb/sdk/wandb_run.py", line 406, in wrapper
    return func(self, *args, **kwargs)
  File "/root/anaconda3/envs/gpt2/lib/python3.10/site-packages/wandb/sdk/wandb_run.py", line 464, in wrapper_fn
    return func(self, *args, **kwargs)
  File "/root/anaconda3/envs/gpt2/lib/python3.10/site-packages/wandb/sdk/wandb_run.py", line 1639, in _console_raw_callback
    self._backend.interface.publish_output_raw(name, data)
  File "/root/anaconda3/envs/gpt2/lib/python3.10/site-packages/wandb/sdk/interface/interface.py", line 762, in publish_output_raw
    self._publish_output_raw(o)
  File "/root/anaconda3/envs/gpt2/lib/python3.10/site-packages/wandb/sdk/interface/interface_shared.py", line 38, in _publish_output_raw
    self._publish(rec)
  File "/root/anaconda3/envs/gpt2/lib/python3.10/site-packages/wandb/sdk/interface/interface_sock.py", line 39, in _publish
    self._sock_client.send_record_publish(record)
  File "/root/anaconda3/envs/gpt2/lib/python3.10/site-packages/wandb/sdk/lib/sock_client.py", line 174, in send_record_publish
    self.send_server_request(server_req)
  File "/root/anaconda3/envs/gpt2/lib/python3.10/site-packages/wandb/sdk/lib/sock_client.py", line 154, in send_server_request
    self._send_message(msg)
  File "/root/anaconda3/envs/gpt2/lib/python3.10/site-packages/wandb/sdk/lib/sock_client.py", line 151, in _send_message
    self._sendall_with_error_handle(header + data)
  File "/root/anaconda3/envs/gpt2/lib/python3.10/site-packages/wandb/sdk/lib/sock_client.py", line 130, in _sendall_with_error_handle
    sent = self._sock.send(data)
BrokenPipeError: [Errno 32] Broken pipe
2025-05-30 17:14:09,643 ERROR   MainThread:1352753 [redirect.py:_on_write():664] [no run ID] error in stderr callback
Traceback (most recent call last):
  File "/root/anaconda3/envs/gpt2/lib/python3.10/multiprocessing/managers.py", line 810, in _callmethod
    conn = self._tls.connection
AttributeError: 'ForkAwareLocal' object has no attribute 'connection'

During handling of the above exception, another exception occurred:

Traceback (most recent call last):
  File "/root/anaconda3/envs/gpt2/lib/python3.10/multiprocessing/util.py", line 300, in _run_finalizers
    finalizer()
  File "/root/anaconda3/envs/gpt2/lib/python3.10/multiprocessing/util.py", line 224, in __call__
    res = self._callback(*self._args, **self._kwargs)
  File "/usr/local/Ascend/ascend-toolkit/latest/python/site-packages/tbe/common/repository_manager/route.py", line 54, in wrapper
    return func(cls, *args, **kwargs)
  File "/usr/local/Ascend/ascend-toolkit/latest/python/site-packages/tbe/common/repository_manager/route.py", line 208, in finalize
    cls.cann_kb_mgr.finalize()
  File "/usr/local/Ascend/ascend-toolkit/latest/python/site-packages/tbe/common/repository_manager/cann_kb_manager/knowledge_bank_manager.py", line 42, in finalize
    self.__static_mgr.close()
  File "/usr/local/Ascend/ascend-toolkit/latest/python/site-packages/tbe/common/repository_manager/cann_kb_manager/base_manager.py", line 339, in close
    for name in copy.deepcopy(self.write_kb.keys()):
  File "<string>", line 2, in keys
  File "/root/anaconda3/envs/gpt2/lib/python3.10/multiprocessing/managers.py", line 814, in _callmethod
    self._connect()
  File "/root/anaconda3/envs/gpt2/lib/python3.10/multiprocessing/managers.py", line 801, in _connect
    conn = self._Client(self._token.address, authkey=self._authkey)
  File "/root/anaconda3/envs/gpt2/lib/python3.10/multiprocessing/connection.py", line 502, in Client
    c = SocketClient(address)
  File "/root/anaconda3/envs/gpt2/lib/python3.10/multiprocessing/connection.py", line 630, in SocketClient
    s.connect(address)
ConnectionRefusedError: [Errno 111] Connection refused

During handling of the above exception, another exception occurred:

Traceback (most recent call last):
  File "/root/anaconda3/envs/gpt2/lib/python3.10/site-packages/wandb/sdk/lib/redirect.py", line 662, in _on_write
    cb(written_data)
  File "/root/anaconda3/envs/gpt2/lib/python3.10/site-packages/wandb/sdk/wandb_run.py", line 2500, in <lambda>
    lambda data: self._console_raw_callback("stderr", data),
  File "/root/anaconda3/envs/gpt2/lib/python3.10/site-packages/wandb/sdk/wandb_run.py", line 406, in wrapper
    return func(self, *args, **kwargs)
  File "/root/anaconda3/envs/gpt2/lib/python3.10/site-packages/wandb/sdk/wandb_run.py", line 464, in wrapper_fn
    return func(self, *args, **kwargs)
  File "/root/anaconda3/envs/gpt2/lib/python3.10/site-packages/wandb/sdk/wandb_run.py", line 1639, in _console_raw_callback
    self._backend.interface.publish_output_raw(name, data)
  File "/root/anaconda3/envs/gpt2/lib/python3.10/site-packages/wandb/sdk/interface/interface.py", line 762, in publish_output_raw
    self._publish_output_raw(o)
  File "/root/anaconda3/envs/gpt2/lib/python3.10/site-packages/wandb/sdk/interface/interface_shared.py", line 38, in _publish_output_raw
    self._publish(rec)
  File "/root/anaconda3/envs/gpt2/lib/python3.10/site-packages/wandb/sdk/interface/interface_sock.py", line 39, in _publish
    self._sock_client.send_record_publish(record)
  File "/root/anaconda3/envs/gpt2/lib/python3.10/site-packages/wandb/sdk/lib/sock_client.py", line 174, in send_record_publish
    self.send_server_request(server_req)
  File "/root/anaconda3/envs/gpt2/lib/python3.10/site-packages/wandb/sdk/lib/sock_client.py", line 154, in send_server_request
    self._send_message(msg)
  File "/root/anaconda3/envs/gpt2/lib/python3.10/site-packages/wandb/sdk/lib/sock_client.py", line 151, in _send_message
    self._sendall_with_error_handle(header + data)
  File "/root/anaconda3/envs/gpt2/lib/python3.10/site-packages/wandb/sdk/lib/sock_client.py", line 130, in _sendall_with_error_handle
    sent = self._sock.send(data)
BrokenPipeError: [Errno 32] Broken pipe
2025-05-30 17:14:09,643 ERROR   MainThread:1352753 [redirect.py:_on_write():664] [no run ID] error in stderr callback
Traceback (most recent call last):
  File "/root/anaconda3/envs/gpt2/lib/python3.10/multiprocessing/managers.py", line 810, in _callmethod
    conn = self._tls.connection
AttributeError: 'ForkAwareLocal' object has no attribute 'connection'

During handling of the above exception, another exception occurred:

Traceback (most recent call last):
  File "/root/anaconda3/envs/gpt2/lib/python3.10/multiprocessing/util.py", line 300, in _run_finalizers
    finalizer()
  File "/root/anaconda3/envs/gpt2/lib/python3.10/multiprocessing/util.py", line 224, in __call__
    res = self._callback(*self._args, **self._kwargs)
  File "/usr/local/Ascend/ascend-toolkit/latest/python/site-packages/tbe/common/repository_manager/route.py", line 54, in wrapper
    return func(cls, *args, **kwargs)
  File "/usr/local/Ascend/ascend-toolkit/latest/python/site-packages/tbe/common/repository_manager/route.py", line 208, in finalize
    cls.cann_kb_mgr.finalize()
  File "/usr/local/Ascend/ascend-toolkit/latest/python/site-packages/tbe/common/repository_manager/cann_kb_manager/knowledge_bank_manager.py", line 42, in finalize
    self.__static_mgr.close()
  File "/usr/local/Ascend/ascend-toolkit/latest/python/site-packages/tbe/common/repository_manager/cann_kb_manager/base_manager.py", line 339, in close
    for name in copy.deepcopy(self.write_kb.keys()):
  File "<string>", line 2, in keys
  File "/root/anaconda3/envs/gpt2/lib/python3.10/multiprocessing/managers.py", line 814, in _callmethod
    self._connect()
  File "/root/anaconda3/envs/gpt2/lib/python3.10/multiprocessing/managers.py", line 801, in _connect
    conn = self._Client(self._token.address, authkey=self._authkey)
  File "/root/anaconda3/envs/gpt2/lib/python3.10/multiprocessing/connection.py", line 502, in Client
    c = SocketClient(address)
  File "/root/anaconda3/envs/gpt2/lib/python3.10/multiprocessing/connection.py", line 630, in SocketClient
    s.connect(address)
ConnectionRefusedError: [Errno 111] Connection refused

During handling of the above exception, another exception occurred:

Traceback (most recent call last):
  File "/root/anaconda3/envs/gpt2/lib/python3.10/site-packages/wandb/sdk/lib/redirect.py", line 662, in _on_write
    cb(written_data)
  File "/root/anaconda3/envs/gpt2/lib/python3.10/site-packages/wandb/sdk/wandb_run.py", line 2500, in <lambda>
    lambda data: self._console_raw_callback("stderr", data),
  File "/root/anaconda3/envs/gpt2/lib/python3.10/site-packages/wandb/sdk/wandb_run.py", line 406, in wrapper
    return func(self, *args, **kwargs)
  File "/root/anaconda3/envs/gpt2/lib/python3.10/site-packages/wandb/sdk/wandb_run.py", line 464, in wrapper_fn
    return func(self, *args, **kwargs)
  File "/root/anaconda3/envs/gpt2/lib/python3.10/site-packages/wandb/sdk/wandb_run.py", line 1639, in _console_raw_callback
    self._backend.interface.publish_output_raw(name, data)
  File "/root/anaconda3/envs/gpt2/lib/python3.10/site-packages/wandb/sdk/interface/interface.py", line 762, in publish_output_raw
    self._publish_output_raw(o)
  File "/root/anaconda3/envs/gpt2/lib/python3.10/site-packages/wandb/sdk/interface/interface_shared.py", line 38, in _publish_output_raw
    self._publish(rec)
  File "/root/anaconda3/envs/gpt2/lib/python3.10/site-packages/wandb/sdk/interface/interface_sock.py", line 39, in _publish
    self._sock_client.send_record_publish(record)
  File "/root/anaconda3/envs/gpt2/lib/python3.10/site-packages/wandb/sdk/lib/sock_client.py", line 174, in send_record_publish
    self.send_server_request(server_req)
  File "/root/anaconda3/envs/gpt2/lib/python3.10/site-packages/wandb/sdk/lib/sock_client.py", line 154, in send_server_request
    self._send_message(msg)
  File "/root/anaconda3/envs/gpt2/lib/python3.10/site-packages/wandb/sdk/lib/sock_client.py", line 151, in _send_message
    self._sendall_with_error_handle(header + data)
  File "/root/anaconda3/envs/gpt2/lib/python3.10/site-packages/wandb/sdk/lib/sock_client.py", line 130, in _sendall_with_error_handle
    sent = self._sock.send(data)
BrokenPipeError: [Errno 32] Broken pipe
2025-05-30 17:14:09,644 ERROR   MainThread:1352753 [redirect.py:_on_write():664] [no run ID] error in stderr callback
Traceback (most recent call last):
  File "/root/anaconda3/envs/gpt2/lib/python3.10/multiprocessing/managers.py", line 810, in _callmethod
    conn = self._tls.connection
AttributeError: 'ForkAwareLocal' object has no attribute 'connection'

During handling of the above exception, another exception occurred:

Traceback (most recent call last):
  File "/root/anaconda3/envs/gpt2/lib/python3.10/multiprocessing/util.py", line 300, in _run_finalizers
    finalizer()
  File "/root/anaconda3/envs/gpt2/lib/python3.10/multiprocessing/util.py", line 224, in __call__
    res = self._callback(*self._args, **self._kwargs)
  File "/usr/local/Ascend/ascend-toolkit/latest/python/site-packages/tbe/common/repository_manager/route.py", line 54, in wrapper
    return func(cls, *args, **kwargs)
  File "/usr/local/Ascend/ascend-toolkit/latest/python/site-packages/tbe/common/repository_manager/route.py", line 208, in finalize
    cls.cann_kb_mgr.finalize()
  File "/usr/local/Ascend/ascend-toolkit/latest/python/site-packages/tbe/common/repository_manager/cann_kb_manager/knowledge_bank_manager.py", line 42, in finalize
    self.__static_mgr.close()
  File "/usr/local/Ascend/ascend-toolkit/latest/python/site-packages/tbe/common/repository_manager/cann_kb_manager/base_manager.py", line 339, in close
    for name in copy.deepcopy(self.write_kb.keys()):
  File "<string>", line 2, in keys
  File "/root/anaconda3/envs/gpt2/lib/python3.10/multiprocessing/managers.py", line 814, in _callmethod
    self._connect()
  File "/root/anaconda3/envs/gpt2/lib/python3.10/multiprocessing/managers.py", line 801, in _connect
    conn = self._Client(self._token.address, authkey=self._authkey)
  File "/root/anaconda3/envs/gpt2/lib/python3.10/multiprocessing/connection.py", line 502, in Client
    c = SocketClient(address)
  File "/root/anaconda3/envs/gpt2/lib/python3.10/multiprocessing/connection.py", line 630, in SocketClient
    s.connect(address)
ConnectionRefusedError: [Errno 111] Connection refused

During handling of the above exception, another exception occurred:

Traceback (most recent call last):
  File "/root/anaconda3/envs/gpt2/lib/python3.10/site-packages/wandb/sdk/lib/redirect.py", line 662, in _on_write
    cb(written_data)
  File "/root/anaconda3/envs/gpt2/lib/python3.10/site-packages/wandb/sdk/wandb_run.py", line 2500, in <lambda>
    lambda data: self._console_raw_callback("stderr", data),
  File "/root/anaconda3/envs/gpt2/lib/python3.10/site-packages/wandb/sdk/wandb_run.py", line 406, in wrapper
    return func(self, *args, **kwargs)
  File "/root/anaconda3/envs/gpt2/lib/python3.10/site-packages/wandb/sdk/wandb_run.py", line 464, in wrapper_fn
    return func(self, *args, **kwargs)
  File "/root/anaconda3/envs/gpt2/lib/python3.10/site-packages/wandb/sdk/wandb_run.py", line 1639, in _console_raw_callback
    self._backend.interface.publish_output_raw(name, data)
  File "/root/anaconda3/envs/gpt2/lib/python3.10/site-packages/wandb/sdk/interface/interface.py", line 762, in publish_output_raw
    self._publish_output_raw(o)
  File "/root/anaconda3/envs/gpt2/lib/python3.10/site-packages/wandb/sdk/interface/interface_shared.py", line 38, in _publish_output_raw
    self._publish(rec)
  File "/root/anaconda3/envs/gpt2/lib/python3.10/site-packages/wandb/sdk/interface/interface_sock.py", line 39, in _publish
    self._sock_client.send_record_publish(record)
  File "/root/anaconda3/envs/gpt2/lib/python3.10/site-packages/wandb/sdk/lib/sock_client.py", line 174, in send_record_publish
    self.send_server_request(server_req)
  File "/root/anaconda3/envs/gpt2/lib/python3.10/site-packages/wandb/sdk/lib/sock_client.py", line 154, in send_server_request
    self._send_message(msg)
  File "/root/anaconda3/envs/gpt2/lib/python3.10/site-packages/wandb/sdk/lib/sock_client.py", line 151, in _send_message
    self._sendall_with_error_handle(header + data)
  File "/root/anaconda3/envs/gpt2/lib/python3.10/site-packages/wandb/sdk/lib/sock_client.py", line 130, in _sendall_with_error_handle
    sent = self._sock.send(data)
BrokenPipeError: [Errno 32] Broken pipe
2025-05-30 17:14:09,645 ERROR   MainThread:1352753 [redirect.py:_on_write():664] [no run ID] error in stderr callback
Traceback (most recent call last):
  File "/root/anaconda3/envs/gpt2/lib/python3.10/multiprocessing/managers.py", line 810, in _callmethod
    conn = self._tls.connection
AttributeError: 'ForkAwareLocal' object has no attribute 'connection'

During handling of the above exception, another exception occurred:

Traceback (most recent call last):
  File "/root/anaconda3/envs/gpt2/lib/python3.10/multiprocessing/util.py", line 300, in _run_finalizers
    finalizer()
  File "/root/anaconda3/envs/gpt2/lib/python3.10/multiprocessing/util.py", line 224, in __call__
    res = self._callback(*self._args, **self._kwargs)
  File "/usr/local/Ascend/ascend-toolkit/latest/python/site-packages/tbe/common/repository_manager/route.py", line 54, in wrapper
    return func(cls, *args, **kwargs)
  File "/usr/local/Ascend/ascend-toolkit/latest/python/site-packages/tbe/common/repository_manager/route.py", line 208, in finalize
    cls.cann_kb_mgr.finalize()
  File "/usr/local/Ascend/ascend-toolkit/latest/python/site-packages/tbe/common/repository_manager/cann_kb_manager/knowledge_bank_manager.py", line 42, in finalize
    self.__static_mgr.close()
  File "/usr/local/Ascend/ascend-toolkit/latest/python/site-packages/tbe/common/repository_manager/cann_kb_manager/base_manager.py", line 339, in close
    for name in copy.deepcopy(self.write_kb.keys()):
  File "<string>", line 2, in keys
  File "/root/anaconda3/envs/gpt2/lib/python3.10/multiprocessing/managers.py", line 814, in _callmethod
    self._connect()
  File "/root/anaconda3/envs/gpt2/lib/python3.10/multiprocessing/managers.py", line 801, in _connect
    conn = self._Client(self._token.address, authkey=self._authkey)
  File "/root/anaconda3/envs/gpt2/lib/python3.10/multiprocessing/connection.py", line 502, in Client
    c = SocketClient(address)
  File "/root/anaconda3/envs/gpt2/lib/python3.10/multiprocessing/connection.py", line 630, in SocketClient
    s.connect(address)
ConnectionRefusedError: [Errno 111] Connection refused

During handling of the above exception, another exception occurred:

Traceback (most recent call last):
  File "/root/anaconda3/envs/gpt2/lib/python3.10/site-packages/wandb/sdk/lib/redirect.py", line 662, in _on_write
    cb(written_data)
  File "/root/anaconda3/envs/gpt2/lib/python3.10/site-packages/wandb/sdk/wandb_run.py", line 2500, in <lambda>
    lambda data: self._console_raw_callback("stderr", data),
  File "/root/anaconda3/envs/gpt2/lib/python3.10/site-packages/wandb/sdk/wandb_run.py", line 406, in wrapper
    return func(self, *args, **kwargs)
  File "/root/anaconda3/envs/gpt2/lib/python3.10/site-packages/wandb/sdk/wandb_run.py", line 464, in wrapper_fn
    return func(self, *args, **kwargs)
  File "/root/anaconda3/envs/gpt2/lib/python3.10/site-packages/wandb/sdk/wandb_run.py", line 1639, in _console_raw_callback
    self._backend.interface.publish_output_raw(name, data)
  File "/root/anaconda3/envs/gpt2/lib/python3.10/site-packages/wandb/sdk/interface/interface.py", line 762, in publish_output_raw
    self._publish_output_raw(o)
  File "/root/anaconda3/envs/gpt2/lib/python3.10/site-packages/wandb/sdk/interface/interface_shared.py", line 38, in _publish_output_raw
    self._publish(rec)
  File "/root/anaconda3/envs/gpt2/lib/python3.10/site-packages/wandb/sdk/interface/interface_sock.py", line 39, in _publish
    self._sock_client.send_record_publish(record)
  File "/root/anaconda3/envs/gpt2/lib/python3.10/site-packages/wandb/sdk/lib/sock_client.py", line 174, in send_record_publish
    self.send_server_request(server_req)
  File "/root/anaconda3/envs/gpt2/lib/python3.10/site-packages/wandb/sdk/lib/sock_client.py", line 154, in send_server_request
    self._send_message(msg)
  File "/root/anaconda3/envs/gpt2/lib/python3.10/site-packages/wandb/sdk/lib/sock_client.py", line 151, in _send_message
    self._sendall_with_error_handle(header + data)
  File "/root/anaconda3/envs/gpt2/lib/python3.10/site-packages/wandb/sdk/lib/sock_client.py", line 130, in _sendall_with_error_handle
    sent = self._sock.send(data)
BrokenPipeError: [Errno 32] Broken pipe
2025-05-30 17:14:09,645 ERROR   MainThread:1352753 [redirect.py:_on_write():664] [no run ID] error in stderr callback
Traceback (most recent call last):
  File "/root/anaconda3/envs/gpt2/lib/python3.10/multiprocessing/managers.py", line 810, in _callmethod
    conn = self._tls.connection
AttributeError: 'ForkAwareLocal' object has no attribute 'connection'

During handling of the above exception, another exception occurred:

Traceback (most recent call last):
  File "/root/anaconda3/envs/gpt2/lib/python3.10/multiprocessing/util.py", line 300, in _run_finalizers
    finalizer()
  File "/root/anaconda3/envs/gpt2/lib/python3.10/multiprocessing/util.py", line 224, in __call__
    res = self._callback(*self._args, **self._kwargs)
  File "/usr/local/Ascend/ascend-toolkit/latest/python/site-packages/tbe/common/repository_manager/route.py", line 54, in wrapper
    return func(cls, *args, **kwargs)
  File "/usr/local/Ascend/ascend-toolkit/latest/python/site-packages/tbe/common/repository_manager/route.py", line 208, in finalize
    cls.cann_kb_mgr.finalize()
  File "/usr/local/Ascend/ascend-toolkit/latest/python/site-packages/tbe/common/repository_manager/cann_kb_manager/knowledge_bank_manager.py", line 42, in finalize
    self.__static_mgr.close()
  File "/usr/local/Ascend/ascend-toolkit/latest/python/site-packages/tbe/common/repository_manager/cann_kb_manager/base_manager.py", line 339, in close
    for name in copy.deepcopy(self.write_kb.keys()):
  File "<string>", line 2, in keys
  File "/root/anaconda3/envs/gpt2/lib/python3.10/multiprocessing/managers.py", line 814, in _callmethod
    self._connect()
  File "/root/anaconda3/envs/gpt2/lib/python3.10/multiprocessing/managers.py", line 801, in _connect
    conn = self._Client(self._token.address, authkey=self._authkey)
  File "/root/anaconda3/envs/gpt2/lib/python3.10/multiprocessing/connection.py", line 502, in Client
    c = SocketClient(address)
  File "/root/anaconda3/envs/gpt2/lib/python3.10/multiprocessing/connection.py", line 630, in SocketClient
    s.connect(address)
ConnectionRefusedError: [Errno 111] Connection refused

During handling of the above exception, another exception occurred:

Traceback (most recent call last):
  File "/root/anaconda3/envs/gpt2/lib/python3.10/site-packages/wandb/sdk/lib/redirect.py", line 662, in _on_write
    cb(written_data)
  File "/root/anaconda3/envs/gpt2/lib/python3.10/site-packages/wandb/sdk/wandb_run.py", line 2500, in <lambda>
    lambda data: self._console_raw_callback("stderr", data),
  File "/root/anaconda3/envs/gpt2/lib/python3.10/site-packages/wandb/sdk/wandb_run.py", line 406, in wrapper
    return func(self, *args, **kwargs)
  File "/root/anaconda3/envs/gpt2/lib/python3.10/site-packages/wandb/sdk/wandb_run.py", line 464, in wrapper_fn
    return func(self, *args, **kwargs)
  File "/root/anaconda3/envs/gpt2/lib/python3.10/site-packages/wandb/sdk/wandb_run.py", line 1639, in _console_raw_callback
    self._backend.interface.publish_output_raw(name, data)
  File "/root/anaconda3/envs/gpt2/lib/python3.10/site-packages/wandb/sdk/interface/interface.py", line 762, in publish_output_raw
    self._publish_output_raw(o)
  File "/root/anaconda3/envs/gpt2/lib/python3.10/site-packages/wandb/sdk/interface/interface_shared.py", line 38, in _publish_output_raw
    self._publish(rec)
  File "/root/anaconda3/envs/gpt2/lib/python3.10/site-packages/wandb/sdk/interface/interface_sock.py", line 39, in _publish
    self._sock_client.send_record_publish(record)
  File "/root/anaconda3/envs/gpt2/lib/python3.10/site-packages/wandb/sdk/lib/sock_client.py", line 174, in send_record_publish
    self.send_server_request(server_req)
  File "/root/anaconda3/envs/gpt2/lib/python3.10/site-packages/wandb/sdk/lib/sock_client.py", line 154, in send_server_request
    self._send_message(msg)
  File "/root/anaconda3/envs/gpt2/lib/python3.10/site-packages/wandb/sdk/lib/sock_client.py", line 151, in _send_message
    self._sendall_with_error_handle(header + data)
  File "/root/anaconda3/envs/gpt2/lib/python3.10/site-packages/wandb/sdk/lib/sock_client.py", line 130, in _sendall_with_error_handle
    sent = self._sock.send(data)
BrokenPipeError: [Errno 32] Broken pipe
2025-05-30 17:14:09,646 ERROR   MainThread:1352753 [redirect.py:_on_write():664] [no run ID] error in stderr callback
Traceback (most recent call last):
  File "/root/anaconda3/envs/gpt2/lib/python3.10/multiprocessing/managers.py", line 810, in _callmethod
    conn = self._tls.connection
AttributeError: 'ForkAwareLocal' object has no attribute 'connection'

During handling of the above exception, another exception occurred:

Traceback (most recent call last):
  File "/root/anaconda3/envs/gpt2/lib/python3.10/multiprocessing/util.py", line 300, in _run_finalizers
    finalizer()
  File "/root/anaconda3/envs/gpt2/lib/python3.10/multiprocessing/util.py", line 224, in __call__
    res = self._callback(*self._args, **self._kwargs)
  File "/usr/local/Ascend/ascend-toolkit/latest/python/site-packages/tbe/common/repository_manager/route.py", line 54, in wrapper
    return func(cls, *args, **kwargs)
  File "/usr/local/Ascend/ascend-toolkit/latest/python/site-packages/tbe/common/repository_manager/route.py", line 208, in finalize
    cls.cann_kb_mgr.finalize()
  File "/usr/local/Ascend/ascend-toolkit/latest/python/site-packages/tbe/common/repository_manager/cann_kb_manager/knowledge_bank_manager.py", line 42, in finalize
    self.__static_mgr.close()
  File "/usr/local/Ascend/ascend-toolkit/latest/python/site-packages/tbe/common/repository_manager/cann_kb_manager/base_manager.py", line 339, in close
    for name in copy.deepcopy(self.write_kb.keys()):
  File "<string>", line 2, in keys
  File "/root/anaconda3/envs/gpt2/lib/python3.10/multiprocessing/managers.py", line 814, in _callmethod
    self._connect()
  File "/root/anaconda3/envs/gpt2/lib/python3.10/multiprocessing/managers.py", line 801, in _connect
    conn = self._Client(self._token.address, authkey=self._authkey)
  File "/root/anaconda3/envs/gpt2/lib/python3.10/multiprocessing/connection.py", line 502, in Client
    c = SocketClient(address)
  File "/root/anaconda3/envs/gpt2/lib/python3.10/multiprocessing/connection.py", line 630, in SocketClient
    s.connect(address)
ConnectionRefusedError: [Errno 111] Connection refused

During handling of the above exception, another exception occurred:

Traceback (most recent call last):
  File "/root/anaconda3/envs/gpt2/lib/python3.10/site-packages/wandb/sdk/lib/redirect.py", line 662, in _on_write
    cb(written_data)
  File "/root/anaconda3/envs/gpt2/lib/python3.10/site-packages/wandb/sdk/wandb_run.py", line 2500, in <lambda>
    lambda data: self._console_raw_callback("stderr", data),
  File "/root/anaconda3/envs/gpt2/lib/python3.10/site-packages/wandb/sdk/wandb_run.py", line 406, in wrapper
    return func(self, *args, **kwargs)
  File "/root/anaconda3/envs/gpt2/lib/python3.10/site-packages/wandb/sdk/wandb_run.py", line 464, in wrapper_fn
    return func(self, *args, **kwargs)
  File "/root/anaconda3/envs/gpt2/lib/python3.10/site-packages/wandb/sdk/wandb_run.py", line 1639, in _console_raw_callback
    self._backend.interface.publish_output_raw(name, data)
  File "/root/anaconda3/envs/gpt2/lib/python3.10/site-packages/wandb/sdk/interface/interface.py", line 762, in publish_output_raw
    self._publish_output_raw(o)
  File "/root/anaconda3/envs/gpt2/lib/python3.10/site-packages/wandb/sdk/interface/interface_shared.py", line 38, in _publish_output_raw
    self._publish(rec)
  File "/root/anaconda3/envs/gpt2/lib/python3.10/site-packages/wandb/sdk/interface/interface_sock.py", line 39, in _publish
    self._sock_client.send_record_publish(record)
  File "/root/anaconda3/envs/gpt2/lib/python3.10/site-packages/wandb/sdk/lib/sock_client.py", line 174, in send_record_publish
    self.send_server_request(server_req)
  File "/root/anaconda3/envs/gpt2/lib/python3.10/site-packages/wandb/sdk/lib/sock_client.py", line 154, in send_server_request
    self._send_message(msg)
  File "/root/anaconda3/envs/gpt2/lib/python3.10/site-packages/wandb/sdk/lib/sock_client.py", line 151, in _send_message
    self._sendall_with_error_handle(header + data)
  File "/root/anaconda3/envs/gpt2/lib/python3.10/site-packages/wandb/sdk/lib/sock_client.py", line 130, in _sendall_with_error_handle
    sent = self._sock.send(data)
BrokenPipeError: [Errno 32] Broken pipe
2025-05-30 17:14:09,646 ERROR   MainThread:1352753 [redirect.py:_on_write():664] [no run ID] error in stderr callback
Traceback (most recent call last):
  File "/root/anaconda3/envs/gpt2/lib/python3.10/multiprocessing/managers.py", line 810, in _callmethod
    conn = self._tls.connection
AttributeError: 'ForkAwareLocal' object has no attribute 'connection'

During handling of the above exception, another exception occurred:

Traceback (most recent call last):
  File "/root/anaconda3/envs/gpt2/lib/python3.10/multiprocessing/util.py", line 300, in _run_finalizers
    finalizer()
  File "/root/anaconda3/envs/gpt2/lib/python3.10/multiprocessing/util.py", line 224, in __call__
    res = self._callback(*self._args, **self._kwargs)
  File "/usr/local/Ascend/ascend-toolkit/latest/python/site-packages/tbe/common/repository_manager/route.py", line 54, in wrapper
    return func(cls, *args, **kwargs)
  File "/usr/local/Ascend/ascend-toolkit/latest/python/site-packages/tbe/common/repository_manager/route.py", line 208, in finalize
    cls.cann_kb_mgr.finalize()
  File "/usr/local/Ascend/ascend-toolkit/latest/python/site-packages/tbe/common/repository_manager/cann_kb_manager/knowledge_bank_manager.py", line 42, in finalize
    self.__static_mgr.close()
  File "/usr/local/Ascend/ascend-toolkit/latest/python/site-packages/tbe/common/repository_manager/cann_kb_manager/base_manager.py", line 339, in close
    for name in copy.deepcopy(self.write_kb.keys()):
  File "<string>", line 2, in keys
  File "/root/anaconda3/envs/gpt2/lib/python3.10/multiprocessing/managers.py", line 814, in _callmethod
    self._connect()
  File "/root/anaconda3/envs/gpt2/lib/python3.10/multiprocessing/managers.py", line 801, in _connect
    conn = self._Client(self._token.address, authkey=self._authkey)
  File "/root/anaconda3/envs/gpt2/lib/python3.10/multiprocessing/connection.py", line 502, in Client
    c = SocketClient(address)
  File "/root/anaconda3/envs/gpt2/lib/python3.10/multiprocessing/connection.py", line 630, in SocketClient
    s.connect(address)
ConnectionRefusedError: [Errno 111] Connection refused

During handling of the above exception, another exception occurred:

Traceback (most recent call last):
  File "/root/anaconda3/envs/gpt2/lib/python3.10/site-packages/wandb/sdk/lib/redirect.py", line 662, in _on_write
    cb(written_data)
  File "/root/anaconda3/envs/gpt2/lib/python3.10/site-packages/wandb/sdk/wandb_run.py", line 2500, in <lambda>
    lambda data: self._console_raw_callback("stderr", data),
  File "/root/anaconda3/envs/gpt2/lib/python3.10/site-packages/wandb/sdk/wandb_run.py", line 406, in wrapper
    return func(self, *args, **kwargs)
  File "/root/anaconda3/envs/gpt2/lib/python3.10/site-packages/wandb/sdk/wandb_run.py", line 464, in wrapper_fn
    return func(self, *args, **kwargs)
  File "/root/anaconda3/envs/gpt2/lib/python3.10/site-packages/wandb/sdk/wandb_run.py", line 1639, in _console_raw_callback
    self._backend.interface.publish_output_raw(name, data)
  File "/root/anaconda3/envs/gpt2/lib/python3.10/site-packages/wandb/sdk/interface/interface.py", line 762, in publish_output_raw
    self._publish_output_raw(o)
  File "/root/anaconda3/envs/gpt2/lib/python3.10/site-packages/wandb/sdk/interface/interface_shared.py", line 38, in _publish_output_raw
    self._publish(rec)
  File "/root/anaconda3/envs/gpt2/lib/python3.10/site-packages/wandb/sdk/interface/interface_sock.py", line 39, in _publish
    self._sock_client.send_record_publish(record)
  File "/root/anaconda3/envs/gpt2/lib/python3.10/site-packages/wandb/sdk/lib/sock_client.py", line 174, in send_record_publish
    self.send_server_request(server_req)
  File "/root/anaconda3/envs/gpt2/lib/python3.10/site-packages/wandb/sdk/lib/sock_client.py", line 154, in send_server_request
    self._send_message(msg)
  File "/root/anaconda3/envs/gpt2/lib/python3.10/site-packages/wandb/sdk/lib/sock_client.py", line 151, in _send_message
    self._sendall_with_error_handle(header + data)
  File "/root/anaconda3/envs/gpt2/lib/python3.10/site-packages/wandb/sdk/lib/sock_client.py", line 130, in _sendall_with_error_handle
    sent = self._sock.send(data)
BrokenPipeError: [Errno 32] Broken pipe
2025-05-30 17:14:09,647 ERROR   MainThread:1352753 [redirect.py:_on_write():664] [no run ID] error in stderr callback
Traceback (most recent call last):
  File "/root/anaconda3/envs/gpt2/lib/python3.10/multiprocessing/managers.py", line 810, in _callmethod
    conn = self._tls.connection
AttributeError: 'ForkAwareLocal' object has no attribute 'connection'

During handling of the above exception, another exception occurred:

Traceback (most recent call last):
  File "/root/anaconda3/envs/gpt2/lib/python3.10/multiprocessing/util.py", line 300, in _run_finalizers
    finalizer()
  File "/root/anaconda3/envs/gpt2/lib/python3.10/multiprocessing/util.py", line 224, in __call__
    res = self._callback(*self._args, **self._kwargs)
  File "/usr/local/Ascend/ascend-toolkit/latest/python/site-packages/tbe/common/repository_manager/route.py", line 54, in wrapper
    return func(cls, *args, **kwargs)
  File "/usr/local/Ascend/ascend-toolkit/latest/python/site-packages/tbe/common/repository_manager/route.py", line 208, in finalize
    cls.cann_kb_mgr.finalize()
  File "/usr/local/Ascend/ascend-toolkit/latest/python/site-packages/tbe/common/repository_manager/cann_kb_manager/knowledge_bank_manager.py", line 42, in finalize
    self.__static_mgr.close()
  File "/usr/local/Ascend/ascend-toolkit/latest/python/site-packages/tbe/common/repository_manager/cann_kb_manager/base_manager.py", line 339, in close
    for name in copy.deepcopy(self.write_kb.keys()):
  File "<string>", line 2, in keys
  File "/root/anaconda3/envs/gpt2/lib/python3.10/multiprocessing/managers.py", line 814, in _callmethod
    self._connect()
  File "/root/anaconda3/envs/gpt2/lib/python3.10/multiprocessing/managers.py", line 801, in _connect
    conn = self._Client(self._token.address, authkey=self._authkey)
  File "/root/anaconda3/envs/gpt2/lib/python3.10/multiprocessing/connection.py", line 502, in Client
    c = SocketClient(address)
  File "/root/anaconda3/envs/gpt2/lib/python3.10/multiprocessing/connection.py", line 630, in SocketClient
    s.connect(address)
ConnectionRefusedError: [Errno 111] Connection refused

During handling of the above exception, another exception occurred:

Traceback (most recent call last):
  File "/root/anaconda3/envs/gpt2/lib/python3.10/site-packages/wandb/sdk/lib/redirect.py", line 662, in _on_write
    cb(written_data)
  File "/root/anaconda3/envs/gpt2/lib/python3.10/site-packages/wandb/sdk/wandb_run.py", line 2500, in <lambda>
    lambda data: self._console_raw_callback("stderr", data),
  File "/root/anaconda3/envs/gpt2/lib/python3.10/site-packages/wandb/sdk/wandb_run.py", line 406, in wrapper
    return func(self, *args, **kwargs)
  File "/root/anaconda3/envs/gpt2/lib/python3.10/site-packages/wandb/sdk/wandb_run.py", line 464, in wrapper_fn
    return func(self, *args, **kwargs)
  File "/root/anaconda3/envs/gpt2/lib/python3.10/site-packages/wandb/sdk/wandb_run.py", line 1639, in _console_raw_callback
    self._backend.interface.publish_output_raw(name, data)
  File "/root/anaconda3/envs/gpt2/lib/python3.10/site-packages/wandb/sdk/interface/interface.py", line 762, in publish_output_raw
    self._publish_output_raw(o)
  File "/root/anaconda3/envs/gpt2/lib/python3.10/site-packages/wandb/sdk/interface/interface_shared.py", line 38, in _publish_output_raw
    self._publish(rec)
  File "/root/anaconda3/envs/gpt2/lib/python3.10/site-packages/wandb/sdk/interface/interface_sock.py", line 39, in _publish
    self._sock_client.send_record_publish(record)
  File "/root/anaconda3/envs/gpt2/lib/python3.10/site-packages/wandb/sdk/lib/sock_client.py", line 174, in send_record_publish
    self.send_server_request(server_req)
  File "/root/anaconda3/envs/gpt2/lib/python3.10/site-packages/wandb/sdk/lib/sock_client.py", line 154, in send_server_request
    self._send_message(msg)
  File "/root/anaconda3/envs/gpt2/lib/python3.10/site-packages/wandb/sdk/lib/sock_client.py", line 151, in _send_message
    self._sendall_with_error_handle(header + data)
  File "/root/anaconda3/envs/gpt2/lib/python3.10/site-packages/wandb/sdk/lib/sock_client.py", line 130, in _sendall_with_error_handle
    sent = self._sock.send(data)
BrokenPipeError: [Errno 32] Broken pipe
2025-05-30 17:14:09,648 ERROR   MainThread:1352753 [redirect.py:_on_write():664] [no run ID] error in stderr callback
Traceback (most recent call last):
  File "/root/anaconda3/envs/gpt2/lib/python3.10/multiprocessing/managers.py", line 810, in _callmethod
    conn = self._tls.connection
AttributeError: 'ForkAwareLocal' object has no attribute 'connection'

During handling of the above exception, another exception occurred:

Traceback (most recent call last):
  File "/root/anaconda3/envs/gpt2/lib/python3.10/multiprocessing/util.py", line 300, in _run_finalizers
    finalizer()
  File "/root/anaconda3/envs/gpt2/lib/python3.10/multiprocessing/util.py", line 224, in __call__
    res = self._callback(*self._args, **self._kwargs)
  File "/usr/local/Ascend/ascend-toolkit/latest/python/site-packages/tbe/common/repository_manager/route.py", line 54, in wrapper
    return func(cls, *args, **kwargs)
  File "/usr/local/Ascend/ascend-toolkit/latest/python/site-packages/tbe/common/repository_manager/route.py", line 208, in finalize
    cls.cann_kb_mgr.finalize()
  File "/usr/local/Ascend/ascend-toolkit/latest/python/site-packages/tbe/common/repository_manager/cann_kb_manager/knowledge_bank_manager.py", line 42, in finalize
    self.__static_mgr.close()
  File "/usr/local/Ascend/ascend-toolkit/latest/python/site-packages/tbe/common/repository_manager/cann_kb_manager/base_manager.py", line 339, in close
    for name in copy.deepcopy(self.write_kb.keys()):
  File "<string>", line 2, in keys
  File "/root/anaconda3/envs/gpt2/lib/python3.10/multiprocessing/managers.py", line 814, in _callmethod
    self._connect()
  File "/root/anaconda3/envs/gpt2/lib/python3.10/multiprocessing/managers.py", line 801, in _connect
    conn = self._Client(self._token.address, authkey=self._authkey)
  File "/root/anaconda3/envs/gpt2/lib/python3.10/multiprocessing/connection.py", line 502, in Client
    c = SocketClient(address)
  File "/root/anaconda3/envs/gpt2/lib/python3.10/multiprocessing/connection.py", line 630, in SocketClient
    s.connect(address)
ConnectionRefusedError: [Errno 111] Connection refused

During handling of the above exception, another exception occurred:

Traceback (most recent call last):
  File "/root/anaconda3/envs/gpt2/lib/python3.10/site-packages/wandb/sdk/lib/redirect.py", line 662, in _on_write
    cb(written_data)
  File "/root/anaconda3/envs/gpt2/lib/python3.10/site-packages/wandb/sdk/wandb_run.py", line 2500, in <lambda>
    lambda data: self._console_raw_callback("stderr", data),
  File "/root/anaconda3/envs/gpt2/lib/python3.10/site-packages/wandb/sdk/wandb_run.py", line 406, in wrapper
    return func(self, *args, **kwargs)
  File "/root/anaconda3/envs/gpt2/lib/python3.10/site-packages/wandb/sdk/wandb_run.py", line 464, in wrapper_fn
    return func(self, *args, **kwargs)
  File "/root/anaconda3/envs/gpt2/lib/python3.10/site-packages/wandb/sdk/wandb_run.py", line 1639, in _console_raw_callback
    self._backend.interface.publish_output_raw(name, data)
  File "/root/anaconda3/envs/gpt2/lib/python3.10/site-packages/wandb/sdk/interface/interface.py", line 762, in publish_output_raw
    self._publish_output_raw(o)
  File "/root/anaconda3/envs/gpt2/lib/python3.10/site-packages/wandb/sdk/interface/interface_shared.py", line 38, in _publish_output_raw
    self._publish(rec)
  File "/root/anaconda3/envs/gpt2/lib/python3.10/site-packages/wandb/sdk/interface/interface_sock.py", line 39, in _publish
    self._sock_client.send_record_publish(record)
  File "/root/anaconda3/envs/gpt2/lib/python3.10/site-packages/wandb/sdk/lib/sock_client.py", line 174, in send_record_publish
    self.send_server_request(server_req)
  File "/root/anaconda3/envs/gpt2/lib/python3.10/site-packages/wandb/sdk/lib/sock_client.py", line 154, in send_server_request
    self._send_message(msg)
  File "/root/anaconda3/envs/gpt2/lib/python3.10/site-packages/wandb/sdk/lib/sock_client.py", line 151, in _send_message
    self._sendall_with_error_handle(header + data)
  File "/root/anaconda3/envs/gpt2/lib/python3.10/site-packages/wandb/sdk/lib/sock_client.py", line 130, in _sendall_with_error_handle
    sent = self._sock.send(data)
BrokenPipeError: [Errno 32] Broken pipe
2025-05-30 17:14:09,648 ERROR   MainThread:1352753 [redirect.py:_on_write():664] [no run ID] error in stderr callback
Traceback (most recent call last):
  File "/root/anaconda3/envs/gpt2/lib/python3.10/multiprocessing/managers.py", line 810, in _callmethod
    conn = self._tls.connection
AttributeError: 'ForkAwareLocal' object has no attribute 'connection'

During handling of the above exception, another exception occurred:

Traceback (most recent call last):
  File "/root/anaconda3/envs/gpt2/lib/python3.10/multiprocessing/util.py", line 300, in _run_finalizers
    finalizer()
  File "/root/anaconda3/envs/gpt2/lib/python3.10/multiprocessing/util.py", line 224, in __call__
    res = self._callback(*self._args, **self._kwargs)
  File "/usr/local/Ascend/ascend-toolkit/latest/python/site-packages/tbe/common/repository_manager/route.py", line 54, in wrapper
    return func(cls, *args, **kwargs)
  File "/usr/local/Ascend/ascend-toolkit/latest/python/site-packages/tbe/common/repository_manager/route.py", line 208, in finalize
    cls.cann_kb_mgr.finalize()
  File "/usr/local/Ascend/ascend-toolkit/latest/python/site-packages/tbe/common/repository_manager/cann_kb_manager/knowledge_bank_manager.py", line 42, in finalize
    self.__static_mgr.close()
  File "/usr/local/Ascend/ascend-toolkit/latest/python/site-packages/tbe/common/repository_manager/cann_kb_manager/base_manager.py", line 339, in close
    for name in copy.deepcopy(self.write_kb.keys()):
  File "<string>", line 2, in keys
  File "/root/anaconda3/envs/gpt2/lib/python3.10/multiprocessing/managers.py", line 814, in _callmethod
    self._connect()
  File "/root/anaconda3/envs/gpt2/lib/python3.10/multiprocessing/managers.py", line 801, in _connect
    conn = self._Client(self._token.address, authkey=self._authkey)
  File "/root/anaconda3/envs/gpt2/lib/python3.10/multiprocessing/connection.py", line 502, in Client
    c = SocketClient(address)
  File "/root/anaconda3/envs/gpt2/lib/python3.10/multiprocessing/connection.py", line 630, in SocketClient
    s.connect(address)
ConnectionRefusedError: [Errno 111] Connection refused

During handling of the above exception, another exception occurred:

Traceback (most recent call last):
  File "/root/anaconda3/envs/gpt2/lib/python3.10/site-packages/wandb/sdk/lib/redirect.py", line 662, in _on_write
    cb(written_data)
  File "/root/anaconda3/envs/gpt2/lib/python3.10/site-packages/wandb/sdk/wandb_run.py", line 2500, in <lambda>
    lambda data: self._console_raw_callback("stderr", data),
  File "/root/anaconda3/envs/gpt2/lib/python3.10/site-packages/wandb/sdk/wandb_run.py", line 406, in wrapper
    return func(self, *args, **kwargs)
  File "/root/anaconda3/envs/gpt2/lib/python3.10/site-packages/wandb/sdk/wandb_run.py", line 464, in wrapper_fn
    return func(self, *args, **kwargs)
  File "/root/anaconda3/envs/gpt2/lib/python3.10/site-packages/wandb/sdk/wandb_run.py", line 1639, in _console_raw_callback
    self._backend.interface.publish_output_raw(name, data)
  File "/root/anaconda3/envs/gpt2/lib/python3.10/site-packages/wandb/sdk/interface/interface.py", line 762, in publish_output_raw
    self._publish_output_raw(o)
  File "/root/anaconda3/envs/gpt2/lib/python3.10/site-packages/wandb/sdk/interface/interface_shared.py", line 38, in _publish_output_raw
    self._publish(rec)
  File "/root/anaconda3/envs/gpt2/lib/python3.10/site-packages/wandb/sdk/interface/interface_sock.py", line 39, in _publish
    self._sock_client.send_record_publish(record)
  File "/root/anaconda3/envs/gpt2/lib/python3.10/site-packages/wandb/sdk/lib/sock_client.py", line 174, in send_record_publish
    self.send_server_request(server_req)
  File "/root/anaconda3/envs/gpt2/lib/python3.10/site-packages/wandb/sdk/lib/sock_client.py", line 154, in send_server_request
    self._send_message(msg)
  File "/root/anaconda3/envs/gpt2/lib/python3.10/site-packages/wandb/sdk/lib/sock_client.py", line 151, in _send_message
    self._sendall_with_error_handle(header + data)
  File "/root/anaconda3/envs/gpt2/lib/python3.10/site-packages/wandb/sdk/lib/sock_client.py", line 130, in _sendall_with_error_handle
    sent = self._sock.send(data)
BrokenPipeError: [Errno 32] Broken pipe
2025-05-30 17:14:09,649 ERROR   MainThread:1352753 [redirect.py:_on_write():664] [no run ID] error in stderr callback
Traceback (most recent call last):
  File "/root/anaconda3/envs/gpt2/lib/python3.10/multiprocessing/managers.py", line 810, in _callmethod
    conn = self._tls.connection
AttributeError: 'ForkAwareLocal' object has no attribute 'connection'

During handling of the above exception, another exception occurred:

Traceback (most recent call last):
  File "/root/anaconda3/envs/gpt2/lib/python3.10/multiprocessing/util.py", line 300, in _run_finalizers
    finalizer()
  File "/root/anaconda3/envs/gpt2/lib/python3.10/multiprocessing/util.py", line 224, in __call__
    res = self._callback(*self._args, **self._kwargs)
  File "/usr/local/Ascend/ascend-toolkit/latest/python/site-packages/tbe/common/repository_manager/route.py", line 54, in wrapper
    return func(cls, *args, **kwargs)
  File "/usr/local/Ascend/ascend-toolkit/latest/python/site-packages/tbe/common/repository_manager/route.py", line 208, in finalize
    cls.cann_kb_mgr.finalize()
  File "/usr/local/Ascend/ascend-toolkit/latest/python/site-packages/tbe/common/repository_manager/cann_kb_manager/knowledge_bank_manager.py", line 42, in finalize
    self.__static_mgr.close()
  File "/usr/local/Ascend/ascend-toolkit/latest/python/site-packages/tbe/common/repository_manager/cann_kb_manager/base_manager.py", line 339, in close
    for name in copy.deepcopy(self.write_kb.keys()):
  File "<string>", line 2, in keys
  File "/root/anaconda3/envs/gpt2/lib/python3.10/multiprocessing/managers.py", line 814, in _callmethod
    self._connect()
  File "/root/anaconda3/envs/gpt2/lib/python3.10/multiprocessing/managers.py", line 801, in _connect
    conn = self._Client(self._token.address, authkey=self._authkey)
  File "/root/anaconda3/envs/gpt2/lib/python3.10/multiprocessing/connection.py", line 502, in Client
    c = SocketClient(address)
  File "/root/anaconda3/envs/gpt2/lib/python3.10/multiprocessing/connection.py", line 630, in SocketClient
    s.connect(address)
ConnectionRefusedError: [Errno 111] Connection refused

During handling of the above exception, another exception occurred:

Traceback (most recent call last):
  File "/root/anaconda3/envs/gpt2/lib/python3.10/site-packages/wandb/sdk/lib/redirect.py", line 662, in _on_write
    cb(written_data)
  File "/root/anaconda3/envs/gpt2/lib/python3.10/site-packages/wandb/sdk/wandb_run.py", line 2500, in <lambda>
    lambda data: self._console_raw_callback("stderr", data),
  File "/root/anaconda3/envs/gpt2/lib/python3.10/site-packages/wandb/sdk/wandb_run.py", line 406, in wrapper
    return func(self, *args, **kwargs)
  File "/root/anaconda3/envs/gpt2/lib/python3.10/site-packages/wandb/sdk/wandb_run.py", line 464, in wrapper_fn
    return func(self, *args, **kwargs)
  File "/root/anaconda3/envs/gpt2/lib/python3.10/site-packages/wandb/sdk/wandb_run.py", line 1639, in _console_raw_callback
    self._backend.interface.publish_output_raw(name, data)
  File "/root/anaconda3/envs/gpt2/lib/python3.10/site-packages/wandb/sdk/interface/interface.py", line 762, in publish_output_raw
    self._publish_output_raw(o)
  File "/root/anaconda3/envs/gpt2/lib/python3.10/site-packages/wandb/sdk/interface/interface_shared.py", line 38, in _publish_output_raw
    self._publish(rec)
  File "/root/anaconda3/envs/gpt2/lib/python3.10/site-packages/wandb/sdk/interface/interface_sock.py", line 39, in _publish
    self._sock_client.send_record_publish(record)
  File "/root/anaconda3/envs/gpt2/lib/python3.10/site-packages/wandb/sdk/lib/sock_client.py", line 174, in send_record_publish
    self.send_server_request(server_req)
  File "/root/anaconda3/envs/gpt2/lib/python3.10/site-packages/wandb/sdk/lib/sock_client.py", line 154, in send_server_request
    self._send_message(msg)
  File "/root/anaconda3/envs/gpt2/lib/python3.10/site-packages/wandb/sdk/lib/sock_client.py", line 151, in _send_message
    self._sendall_with_error_handle(header + data)
  File "/root/anaconda3/envs/gpt2/lib/python3.10/site-packages/wandb/sdk/lib/sock_client.py", line 130, in _sendall_with_error_handle
    sent = self._sock.send(data)
BrokenPipeError: [Errno 32] Broken pipe
2025-05-30 17:14:09,649 ERROR   MainThread:1352753 [redirect.py:_on_write():664] [no run ID] error in stderr callback
Traceback (most recent call last):
  File "/root/anaconda3/envs/gpt2/lib/python3.10/multiprocessing/managers.py", line 810, in _callmethod
    conn = self._tls.connection
AttributeError: 'ForkAwareLocal' object has no attribute 'connection'

During handling of the above exception, another exception occurred:

Traceback (most recent call last):
  File "/root/anaconda3/envs/gpt2/lib/python3.10/multiprocessing/util.py", line 300, in _run_finalizers
    finalizer()
  File "/root/anaconda3/envs/gpt2/lib/python3.10/multiprocessing/util.py", line 224, in __call__
    res = self._callback(*self._args, **self._kwargs)
  File "/usr/local/Ascend/ascend-toolkit/latest/python/site-packages/tbe/common/repository_manager/route.py", line 54, in wrapper
    return func(cls, *args, **kwargs)
  File "/usr/local/Ascend/ascend-toolkit/latest/python/site-packages/tbe/common/repository_manager/route.py", line 208, in finalize
    cls.cann_kb_mgr.finalize()
  File "/usr/local/Ascend/ascend-toolkit/latest/python/site-packages/tbe/common/repository_manager/cann_kb_manager/knowledge_bank_manager.py", line 42, in finalize
    self.__static_mgr.close()
  File "/usr/local/Ascend/ascend-toolkit/latest/python/site-packages/tbe/common/repository_manager/cann_kb_manager/base_manager.py", line 339, in close
    for name in copy.deepcopy(self.write_kb.keys()):
  File "<string>", line 2, in keys
  File "/root/anaconda3/envs/gpt2/lib/python3.10/multiprocessing/managers.py", line 814, in _callmethod
    self._connect()
  File "/root/anaconda3/envs/gpt2/lib/python3.10/multiprocessing/managers.py", line 801, in _connect
    conn = self._Client(self._token.address, authkey=self._authkey)
  File "/root/anaconda3/envs/gpt2/lib/python3.10/multiprocessing/connection.py", line 502, in Client
    c = SocketClient(address)
  File "/root/anaconda3/envs/gpt2/lib/python3.10/multiprocessing/connection.py", line 630, in SocketClient
    s.connect(address)
ConnectionRefusedError: [Errno 111] Connection refused

During handling of the above exception, another exception occurred:

Traceback (most recent call last):
  File "/root/anaconda3/envs/gpt2/lib/python3.10/site-packages/wandb/sdk/lib/redirect.py", line 662, in _on_write
    cb(written_data)
  File "/root/anaconda3/envs/gpt2/lib/python3.10/site-packages/wandb/sdk/wandb_run.py", line 2500, in <lambda>
    lambda data: self._console_raw_callback("stderr", data),
  File "/root/anaconda3/envs/gpt2/lib/python3.10/site-packages/wandb/sdk/wandb_run.py", line 406, in wrapper
    return func(self, *args, **kwargs)
  File "/root/anaconda3/envs/gpt2/lib/python3.10/site-packages/wandb/sdk/wandb_run.py", line 464, in wrapper_fn
    return func(self, *args, **kwargs)
  File "/root/anaconda3/envs/gpt2/lib/python3.10/site-packages/wandb/sdk/wandb_run.py", line 1639, in _console_raw_callback
    self._backend.interface.publish_output_raw(name, data)
  File "/root/anaconda3/envs/gpt2/lib/python3.10/site-packages/wandb/sdk/interface/interface.py", line 762, in publish_output_raw
    self._publish_output_raw(o)
  File "/root/anaconda3/envs/gpt2/lib/python3.10/site-packages/wandb/sdk/interface/interface_shared.py", line 38, in _publish_output_raw
    self._publish(rec)
  File "/root/anaconda3/envs/gpt2/lib/python3.10/site-packages/wandb/sdk/interface/interface_sock.py", line 39, in _publish
    self._sock_client.send_record_publish(record)
  File "/root/anaconda3/envs/gpt2/lib/python3.10/site-packages/wandb/sdk/lib/sock_client.py", line 174, in send_record_publish
    self.send_server_request(server_req)
  File "/root/anaconda3/envs/gpt2/lib/python3.10/site-packages/wandb/sdk/lib/sock_client.py", line 154, in send_server_request
    self._send_message(msg)
  File "/root/anaconda3/envs/gpt2/lib/python3.10/site-packages/wandb/sdk/lib/sock_client.py", line 151, in _send_message
    self._sendall_with_error_handle(header + data)
  File "/root/anaconda3/envs/gpt2/lib/python3.10/site-packages/wandb/sdk/lib/sock_client.py", line 130, in _sendall_with_error_handle
    sent = self._sock.send(data)
BrokenPipeError: [Errno 32] Broken pipe
2025-05-30 17:14:09,650 ERROR   MainThread:1352753 [redirect.py:_on_write():664] [no run ID] error in stderr callback
Traceback (most recent call last):
  File "/root/anaconda3/envs/gpt2/lib/python3.10/multiprocessing/managers.py", line 810, in _callmethod
    conn = self._tls.connection
AttributeError: 'ForkAwareLocal' object has no attribute 'connection'

During handling of the above exception, another exception occurred:

Traceback (most recent call last):
  File "/root/anaconda3/envs/gpt2/lib/python3.10/multiprocessing/util.py", line 300, in _run_finalizers
    finalizer()
  File "/root/anaconda3/envs/gpt2/lib/python3.10/multiprocessing/util.py", line 224, in __call__
    res = self._callback(*self._args, **self._kwargs)
  File "/usr/local/Ascend/ascend-toolkit/latest/python/site-packages/tbe/common/repository_manager/route.py", line 54, in wrapper
    return func(cls, *args, **kwargs)
  File "/usr/local/Ascend/ascend-toolkit/latest/python/site-packages/tbe/common/repository_manager/route.py", line 208, in finalize
    cls.cann_kb_mgr.finalize()
  File "/usr/local/Ascend/ascend-toolkit/latest/python/site-packages/tbe/common/repository_manager/cann_kb_manager/knowledge_bank_manager.py", line 42, in finalize
    self.__static_mgr.close()
  File "/usr/local/Ascend/ascend-toolkit/latest/python/site-packages/tbe/common/repository_manager/cann_kb_manager/base_manager.py", line 339, in close
    for name in copy.deepcopy(self.write_kb.keys()):
  File "<string>", line 2, in keys
  File "/root/anaconda3/envs/gpt2/lib/python3.10/multiprocessing/managers.py", line 814, in _callmethod
    self._connect()
  File "/root/anaconda3/envs/gpt2/lib/python3.10/multiprocessing/managers.py", line 801, in _connect
    conn = self._Client(self._token.address, authkey=self._authkey)
  File "/root/anaconda3/envs/gpt2/lib/python3.10/multiprocessing/connection.py", line 502, in Client
    c = SocketClient(address)
  File "/root/anaconda3/envs/gpt2/lib/python3.10/multiprocessing/connection.py", line 630, in SocketClient
    s.connect(address)
ConnectionRefusedError: [Errno 111] Connection refused

During handling of the above exception, another exception occurred:

Traceback (most recent call last):
  File "/root/anaconda3/envs/gpt2/lib/python3.10/site-packages/wandb/sdk/lib/redirect.py", line 662, in _on_write
    cb(written_data)
  File "/root/anaconda3/envs/gpt2/lib/python3.10/site-packages/wandb/sdk/wandb_run.py", line 2500, in <lambda>
    lambda data: self._console_raw_callback("stderr", data),
  File "/root/anaconda3/envs/gpt2/lib/python3.10/site-packages/wandb/sdk/wandb_run.py", line 406, in wrapper
    return func(self, *args, **kwargs)
  File "/root/anaconda3/envs/gpt2/lib/python3.10/site-packages/wandb/sdk/wandb_run.py", line 464, in wrapper_fn
    return func(self, *args, **kwargs)
  File "/root/anaconda3/envs/gpt2/lib/python3.10/site-packages/wandb/sdk/wandb_run.py", line 1639, in _console_raw_callback
    self._backend.interface.publish_output_raw(name, data)
  File "/root/anaconda3/envs/gpt2/lib/python3.10/site-packages/wandb/sdk/interface/interface.py", line 762, in publish_output_raw
    self._publish_output_raw(o)
  File "/root/anaconda3/envs/gpt2/lib/python3.10/site-packages/wandb/sdk/interface/interface_shared.py", line 38, in _publish_output_raw
    self._publish(rec)
  File "/root/anaconda3/envs/gpt2/lib/python3.10/site-packages/wandb/sdk/interface/interface_sock.py", line 39, in _publish
    self._sock_client.send_record_publish(record)
  File "/root/anaconda3/envs/gpt2/lib/python3.10/site-packages/wandb/sdk/lib/sock_client.py", line 174, in send_record_publish
    self.send_server_request(server_req)
  File "/root/anaconda3/envs/gpt2/lib/python3.10/site-packages/wandb/sdk/lib/sock_client.py", line 154, in send_server_request
    self._send_message(msg)
  File "/root/anaconda3/envs/gpt2/lib/python3.10/site-packages/wandb/sdk/lib/sock_client.py", line 151, in _send_message
    self._sendall_with_error_handle(header + data)
  File "/root/anaconda3/envs/gpt2/lib/python3.10/site-packages/wandb/sdk/lib/sock_client.py", line 130, in _sendall_with_error_handle
    sent = self._sock.send(data)
BrokenPipeError: [Errno 32] Broken pipe
2025-05-30 17:14:09,651 ERROR   MainThread:1352753 [redirect.py:_on_write():664] [no run ID] error in stderr callback
Traceback (most recent call last):
  File "/root/anaconda3/envs/gpt2/lib/python3.10/multiprocessing/managers.py", line 810, in _callmethod
    conn = self._tls.connection
AttributeError: 'ForkAwareLocal' object has no attribute 'connection'

During handling of the above exception, another exception occurred:

Traceback (most recent call last):
  File "/root/anaconda3/envs/gpt2/lib/python3.10/multiprocessing/util.py", line 300, in _run_finalizers
    finalizer()
  File "/root/anaconda3/envs/gpt2/lib/python3.10/multiprocessing/util.py", line 224, in __call__
    res = self._callback(*self._args, **self._kwargs)
  File "/usr/local/Ascend/ascend-toolkit/latest/python/site-packages/tbe/common/repository_manager/route.py", line 54, in wrapper
    return func(cls, *args, **kwargs)
  File "/usr/local/Ascend/ascend-toolkit/latest/python/site-packages/tbe/common/repository_manager/route.py", line 208, in finalize
    cls.cann_kb_mgr.finalize()
  File "/usr/local/Ascend/ascend-toolkit/latest/python/site-packages/tbe/common/repository_manager/cann_kb_manager/knowledge_bank_manager.py", line 42, in finalize
    self.__static_mgr.close()
  File "/usr/local/Ascend/ascend-toolkit/latest/python/site-packages/tbe/common/repository_manager/cann_kb_manager/base_manager.py", line 339, in close
    for name in copy.deepcopy(self.write_kb.keys()):
  File "<string>", line 2, in keys
  File "/root/anaconda3/envs/gpt2/lib/python3.10/multiprocessing/managers.py", line 814, in _callmethod
    self._connect()
  File "/root/anaconda3/envs/gpt2/lib/python3.10/multiprocessing/managers.py", line 801, in _connect
    conn = self._Client(self._token.address, authkey=self._authkey)
  File "/root/anaconda3/envs/gpt2/lib/python3.10/multiprocessing/connection.py", line 502, in Client
    c = SocketClient(address)
  File "/root/anaconda3/envs/gpt2/lib/python3.10/multiprocessing/connection.py", line 630, in SocketClient
    s.connect(address)
ConnectionRefusedError: [Errno 111] Connection refused

During handling of the above exception, another exception occurred:

Traceback (most recent call last):
  File "/root/anaconda3/envs/gpt2/lib/python3.10/site-packages/wandb/sdk/lib/redirect.py", line 662, in _on_write
    cb(written_data)
  File "/root/anaconda3/envs/gpt2/lib/python3.10/site-packages/wandb/sdk/wandb_run.py", line 2500, in <lambda>
    lambda data: self._console_raw_callback("stderr", data),
  File "/root/anaconda3/envs/gpt2/lib/python3.10/site-packages/wandb/sdk/wandb_run.py", line 406, in wrapper
    return func(self, *args, **kwargs)
  File "/root/anaconda3/envs/gpt2/lib/python3.10/site-packages/wandb/sdk/wandb_run.py", line 464, in wrapper_fn
    return func(self, *args, **kwargs)
  File "/root/anaconda3/envs/gpt2/lib/python3.10/site-packages/wandb/sdk/wandb_run.py", line 1639, in _console_raw_callback
    self._backend.interface.publish_output_raw(name, data)
  File "/root/anaconda3/envs/gpt2/lib/python3.10/site-packages/wandb/sdk/interface/interface.py", line 762, in publish_output_raw
    self._publish_output_raw(o)
  File "/root/anaconda3/envs/gpt2/lib/python3.10/site-packages/wandb/sdk/interface/interface_shared.py", line 38, in _publish_output_raw
    self._publish(rec)
  File "/root/anaconda3/envs/gpt2/lib/python3.10/site-packages/wandb/sdk/interface/interface_sock.py", line 39, in _publish
    self._sock_client.send_record_publish(record)
  File "/root/anaconda3/envs/gpt2/lib/python3.10/site-packages/wandb/sdk/lib/sock_client.py", line 174, in send_record_publish
    self.send_server_request(server_req)
  File "/root/anaconda3/envs/gpt2/lib/python3.10/site-packages/wandb/sdk/lib/sock_client.py", line 154, in send_server_request
    self._send_message(msg)
  File "/root/anaconda3/envs/gpt2/lib/python3.10/site-packages/wandb/sdk/lib/sock_client.py", line 151, in _send_message
    self._sendall_with_error_handle(header + data)
  File "/root/anaconda3/envs/gpt2/lib/python3.10/site-packages/wandb/sdk/lib/sock_client.py", line 130, in _sendall_with_error_handle
    sent = self._sock.send(data)
BrokenPipeError: [Errno 32] Broken pipe
